Workbook

Sheet HASIL PROD
C1: OKEY | H1: CHAMP AYAM | M1: CHAMP SAPI | R1: CHAMP OTAK-OTAK | W1: Fiesta | Z1: KARANTINA | AF1: PVDC WIRE | AQ1: RELEASE
B2: KODE BATCH | C2: Hasil | E2: PVDC | G2: WIRE | H2: Hasil | J2: PVDC | L2: WIRE | M2: Hasil | O2: PVDC | Q2: WIRE | R2: Hasil | T2: PVDC | V2: WIRE | W2: Hasil | AF2: Okey | AH2: C. Ayam | AJ2: C. Sapi | AL2: C. Otak2 | AN2: Fiesta
C3: Box | D3: Kg | E3: PEMAKAIAN | F3: ROLL | G3: PEMAKAIAN | H3: Box | I3: Kg | J3: PEMAKAIAN | K3: ROLL | L3: PEMAKAIAN | M3: Box | N3: Kg | O3: PEMAKAIAN | P3: ROLL | Q3: PEMAKAIAN | R3: Box | S3: Kg | T3: STD | U3: Actual | V3: STD | W3: Box | X3: Kg | Z3: Okey | AA3: C. Ayam | AB3: C. Sapi | AC3: C. Otak2 | AD3: Fiesta | AF3: PVDC | AG3: WIRE | AH3: PVDC | AI3: WIRE | AJ3: PVDC | AK3: WIRE | AL3: PVDC | AM3: WIRE | AN3: PVDC | AO3: WIRE | AQ3: Okey | AR3: C. Ayam | AS3: C. Sapi | AT3: C. Otak2 | AU3: Fiesta
A4: =+'ALL SORTASI'!A6 -> 46204 | B4: QG01701 | C4: 435 | D4: =+C4*3.875 -> 1685.625 | E4: =+D4/0.0125*0.125 -> 16856.25 | F4: =+E4/1500 -> 11.2375 | G4: =+D4/0.0125*0.000318 -> 42.8823 | H4: 463 | I4: =+H4*3.276 -> 1516.788 | J4: =+I4/0.0185*0.185 -> 15167.88 | K4: =+J4/1500 -> 10.11192 | L4: =+I4/0.0185*0.000318 -> 26.072356 | N4: =+M4*3.276 -> 0 | O4: =+N4/0.0185*0.185 -> 0 | P4: =+O4/1500 -> 0 | Q4: =+N4/0.0185*0.000318 -> 0 | S4: =+R4*3.276 -> 0 | T4: =+S4/0.0185*0.185 -> 0 | U4: =+T4/1500 -> 0 | V4: =+S4/0.0185*0.000318 -> 0 | X4: =+W4*2.4 -> 0 | Z4: =IFERROR((D4/'REKAPAN OKEY AYAM'!$AC4),"-") -> 0.1642682 | AA4: =IFERROR((I4/'REKAPAN CHAMP AYAM'!$AC4),"-") -> 0.89818798 | AB4: =IFERROR((N4/'REKAPAN CHAMP SAPI'!AC4),"-") -> - | AC4: =IFERROR((S4/'REKAPAN CHAMP OTAK-OTAK'!AC4),"-") -> - | AD4: =IFERROR((X4/'REKAPAN FIESTA'!AC4),"-") -> - | AF4: =IFERROR(((D4/0.0125*0.125)/F4),"-") -> 1500 | AG4: =IFERROR(((D4/0.0125*0.000318)/#REF!),"-") -> - | AH4: =IFERROR(((I4/0.0185*0.185)/K4),"-") -> 1500 | AI4: =IFERROR(((I4/0.0185*0.000318)/#REF!),"-") -> - | AJ4: =IFERROR(((N4/0.0185*0.185)/P4),"-") -> - | AK4: =IFERROR(((N4/0.0185*0.000318)/#REF!),"-") -> - | AL4: =IFERROR(((S4/0.0185*0.185)/U4),"-") -> - | AM4: =IFERROR(((S4/0.0185*0.000318)/#REF!),"-") -> - | AQ4: =IFERROR(('REKAPAN OKEY AYAM'!$AD4),"-") -> 0.9693712 | AR4: =IFERROR(('REKAPAN CHAMP AYAM'!$AD4),"-") -> 0.85744943 | AS4: =IFERROR(('REKAPAN CHAMP SAPI'!$AD4),"-") -> - | AT4: =IFERROR(('REKAPAN CHAMP OTAK-OTAK'!$AD4),"-") -> - | AU4: =IFERROR(('REKAPAN FIESTA'!$AD4),"-") -> -
A5: =+$A$4 -> 46204 | B5: QG01702 | C5: 413 | D5: =+C5*3.875 -> 1600.375 | E5: =+D5/0.0125*0.125 -> 16003.75 | F5: =+E5/1500 -> 10.669167 | G5: =+D5/0.0125*0.000318 -> 40.71354 | I5: =+H5*3.276 -> 0 | J5: =+I5/0.0185*0.185 -> 0 | K5: =+J5/1500 -> 0 | L5: =+I5/0.0185*0.000318 -> 0 | N5: =+M5*3.276 -> 0 | O5: =+N5/0.0185*0.185 -> 0 | P5: =+O5/1500 -> 0 | Q5: =+N5/0.0185*0.000318 -> 0 | S5: =+R5*3.276 -> 0 | T5: =+S5/0.0185*0.185 -> 0 | U5: =+T5/1500 -> 0 | V5: =+S5/0.0185*0.000318 -> 0
A6: =+$A$4 -> 46204 | B6: QG01703 | C6: 447 | D6: =+C6*3.875 -> 1732.125 | E6: =+D6/0.0125*0.125 -> 17321.25 | F6: =+E6/1500 -> 11.5475 | G6: =+D6/0.0125*0.000318 -> 44.06526 | I6: =+H6*3.276 -> 0 | J6: =+I6/0.0185*0.185 -> 0 | K6: =+J6/1500 -> 0 | L6: =+I6/0.0185*0.000318 -> 0 | N6: =+M6*3.276 -> 0 | O6: =+N6/0.0185*0.185 -> 0 | P6: =+O6/1500 -> 0 | Q6: =+N6/0.0185*0.000318 -> 0 | S6: =+R6*3.276 -> 0 | T6: =+S6/0.0185*0.185 -> 0 | U6: =+T6/1500 -> 0 | V6: =+S6/0.0185*0.000318 -> 0
A7: =+$A$4 -> 46204 | B7: QG01704 | C7: 481 | D7: =+C7*3.875 -> 1863.875 | E7: =+D7/0.0125*0.125 -> 18638.75 | F7: =+E7/1500 -> 12.425833 | G7: =+D7/0.0125*0.000318 -> 47.41698 | I7: =+H7*3.276 -> 0 | J7: =+I7/0.0185*0.185 -> 0 | K7: =+J7/1500 -> 0 | L7: =+I7/0.0185*0.000318 -> 0 | N7: =+M7*3.276 -> 0 | O7: =+N7/0.0185*0.185 -> 0 | P7: =+O7/1500 -> 0 | Q7: =+N7/0.0185*0.000318 -> 0 | S7: =+R7*3.276 -> 0 | T7: =+S7/0.0185*0.185 -> 0 | U7: =+T7/1500 -> 0 | V7: =+S7/0.0185*0.000318 -> 0
A8: =+$A$4 -> 46204 | B8: QG01705 | C8: 467 | D8: =+C8*3.875 -> 1809.625 | E8: =+D8/0.0125*0.125 -> 18096.25 | F8: =+E8/1500 -> 12.064167 | G8: =+D8/0.0125*0.000318 -> 46.03686 | I8: =+H8*3.276 -> 0 | J8: =+I8/0.0185*0.185 -> 0 | K8: =+J8/1500 -> 0 | L8: =+I8/0.0185*0.000318 -> 0 | N8: =+M8*3.276 -> 0 | O8: =+N8/0.0185*0.185 -> 0 | P8: =+O8/1500 -> 0 | Q8: =+N8/0.0185*0.000318 -> 0 | S8: =+R8*3.276 -> 0 | T8: =+S8/0.0185*0.185 -> 0 | U8: =+T8/1500 -> 0 | V8: =+S8/0.0185*0.000318 -> 0
A9: =+$A$4 -> 46204 | B9: QG01706 | C9: 290 | D9: =+C9*3.875 -> 1123.75 | E9: =+D9/0.0125*0.125 -> 11237.5 | F9: =+E9/1500 -> 7.4916667 | G9: =+D9/0.0125*0.000318 -> 28.5882 | I9: =+H9*3.276 -> 0 | J9: =+I9/0.0185*0.185 -> 0 | K9: =+J9/1500 -> 0 | L9: =+I9/0.0185*0.000318 -> 0 | N9: =+M9*3.276 -> 0 | O9: =+N9/0.0185*0.185 -> 0 | P9: =+O9/1500 -> 0 | Q9: =+N9/0.0185*0.000318 -> 0 | S9: =+R9*3.276 -> 0 | T9: =+S9/0.0185*0.185 -> 0 | U9: =+T9/1500 -> 0 | V9: =+S9/0.0185*0.000318 -> 0
A10: =+$A$4 -> 46204 | B10: QG01707 | C10: 102 | D10: =+C10*3.875 -> 395.25 | E10: =+D10/0.0125*0.125 -> 3952.5 | F10: =+E10/1500 -> 2.635 | G10: =+D10/0.0125*0.000318 -> 10.05516 | I10: =+H10*3.276 -> 0 | J10: =+I10/0.0185*0.185 -> 0 | K10: =+J10/1500 -> 0 | L10: =+I10/0.0185*0.000318 -> 0 | N10: =+M10*3.276 -> 0 | O10: =+N10/0.0185*0.185 -> 0 | P10: =+O10/1500 -> 0 | Q10: =+N10/0.0185*0.000318 -> 0 | S10: =+R10*3.276 -> 0 | T10: =+S10/0.0185*0.185 -> 0 | U10: =+T10/1500 -> 0 | V10: =+S10/0.0185*0.000318 -> 0
A11: =+$A$4 -> 46204 | D11: =+C11*3.875 -> 0 | E11: =+D11/0.0125*0.125 -> 0 | F11: =+E11/1500 -> 0 | G11: =+D11/0.0125*0.000318 -> 0 | I11: =+H11*3.276 -> 0 | J11: =+I11/0.0185*0.185 -> 0 | K11: =+J11/1500 -> 0 | L11: =+I11/0.0185*0.000318 -> 0 | N11: =+M11*3.276 -> 0 | O11: =+N11/0.0185*0.185 -> 0 | P11: =+O11/1500 -> 0 | Q11: =+N11/0.0185*0.000318 -> 0 | S11: =+R11*3.276 -> 0 | T11: =+S11/0.0185*0.185 -> 0 | U11: =+T11/1500 -> 0 | V11: =+S11/0.0185*0.000318 -> 0
A12: =+$A$4 -> 46204 | D12: =+C12*3.875 -> 0 | E12: =+D12/0.0125*0.125 -> 0 | F12: =+E12/1500 -> 0 | G12: =+D12/0.0125*0.000318 -> 0 | I12: =+H12*3.276 -> 0 | J12: =+I12/0.0185*0.185 -> 0 | K12: =+J12/1500 -> 0 | L12: =+I12/0.0185*0.000318 -> 0 | N12: =+M12*3.276 -> 0 | O12: =+N12/0.0185*0.185 -> 0 | P12: =+O12/1500 -> 0 | Q12: =+N12/0.0185*0.000318 -> 0 | S12: =+R12*3.276 -> 0 | T12: =+S12/0.0185*0.185 -> 0 | U12: =+T12/1500 -> 0 | V12: =+S12/0.0185*0.000318 -> 0
A13: =+$A$4 -> 46204 | D13: =+C13*3.875 -> 0 | E13: =+D13/0.0125*0.125 -> 0 | F13: =+E13/1500 -> 0 | G13: =+D13/0.0125*0.000318 -> 0 | I13: =+H13*3.276 -> 0 | J13: =+I13/0.0185*0.185 -> 0 | K13: =+J13/1500 -> 0 | L13: =+I13/0.0185*0.000318 -> 0 | N13: =+M13*3.276 -> 0 | O13: =+N13/0.0185*0.185 -> 0 | P13: =+O13/1500 -> 0 | Q13: =+N13/0.0185*0.000318 -> 0 | S13: =+R13*3.276 -> 0 | T13: =+S13/0.0185*0.185 -> 0 | U13: =+T13/1500 -> 0 | V13: =+S13/0.0185*0.000318 -> 0
B14: TOTAL | C14: =SUM(C4:C13) -> 2635 | D14: =+C14*3.875 -> 10210.625 | E14: =SUM(E4:E13) -> 102106.25 | F14: =SUM(F4:F13) -> 68.070833 | G14: =SUM(G4:G13) -> 259.7583 | H14: =SUM(H4:H13) -> 463 | I14: =+H14*3.276 -> 1516.788 | J14: =SUM(J4:J13) -> 15167.88 | K14: =SUM(K4:K13) -> 10.11192 | L14: =SUM(L4:L13) -> 26.072356 | M14: =SUM(M4:M13) -> 0 | N14: =+M14*3.276 -> 0 | O14: =SUM(O4:O13) -> 0 | P14: =SUM(P4:P13) -> 0 | Q14: =SUM(Q4:Q13) -> 0 | R14: =SUM(R4:R13) -> 0 | S14: =+R14*3.276 -> 0 | T14: =SUM(T4:T13) -> 0 | U14: =SUM(U4:U13) -> 0 | V14: =SUM(V4:V13) -> 0
A15: =+A4+1 -> 46205 | B15: QG02701 | D15: =+C15*3.875 -> 0 | E15: =+D15/0.0125*0.125 -> 0 | F15: =+E15/1500 -> 0 | G15: =+D15/0.0125*0.000318 -> 0 | H15: 469 | I15: =+H15*3.276 -> 1536.444 | J15: =+I15/0.0185*0.185 -> 15364.44 | K15: =+J15/1500 -> 10.24296 | L15: =+I15/0.0185*0.000318 -> 26.410227 | N15: =+M15*3.276 -> 0 | O15: =+N15/0.0185*0.185 -> 0 | P15: =+O15/1500 -> 0 | Q15: =+N15/0.0185*0.000318 -> 0 | S15: =+R15*3.276 -> 0 | T15: =+S15/0.0185*0.185 -> 0 | U15: =+T15/1500 -> 0 | V15: =+S15/0.0185*0.000318 -> 0 | X15: =+W15*2.4 -> 0 | Z15: =IFERROR((D15/'REKAPAN OKEY AYAM'!$AC5),"-") -> - | AA15: =IFERROR((I15/'REKAPAN CHAMP AYAM'!$AC5),"-") -> 0.10109195 | AB15: =IFERROR((N15/'REKAPAN CHAMP SAPI'!AC5),"-") -> - | AC15: =IFERROR((S15/'REKAPAN CHAMP OTAK-OTAK'!AC5),"-") -> - | AD15: =IFERROR((X15/'REKAPAN FIESTA'!AC5),"-") -> - | AF15: =IFERROR(((D15/0.0125*0.125)/F15),"-") -> - | AG15: =IFERROR(((D15/0.0125*0.000318)/#REF!),"-") -> - | AH15: =IFERROR(((I15/0.0185*0.185)/K15),"-") -> 1500 | AI15: =IFERROR(((I15/0.0185*0.000318)/#REF!),"-") -> - | AJ15: =IFERROR(((N15/0.0185*0.185)/P15),"-") -> - | AK15: =IFERROR(((N15/0.0185*0.000318)/#REF!),"-") -> - | AL15: =IFERROR(((S15/0.0185*0.185)/U15),"-") -> - | AM15: =IFERROR(((S15/0.0185*0.000318)/#REF!),"-") -> - | AQ15: =IFERROR(('REKAPAN OKEY AYAM'!$AD5),"-") -> - | AR15: =IFERROR(('REKAPAN CHAMP AYAM'!$AD5),"-") -> 0.90443886 | AS15: =IFERROR(('REKAPAN CHAMP SAPI'!$AD5),"-") -> - | AT15: =IFERROR(('REKAPAN CHAMP OTAK-OTAK'!$AD5),"-") -> - | AU15: =IFERROR(('REKAPAN FIESTA'!$AD5),"-") -> -
A16: =+$A15 -> 46205 | B16: QG02702 | D16: =+C16*3.875 -> 0 | E16: =+D16/0.0125*0.125 -> 0 | F16: =+E16/1500 -> 0 | G16: =+D16/0.0125*0.000318 -> 0 | H16: 493 | I16: =+H16*3.276 -> 1615.068 | J16: =+I16/0.0185*0.185 -> 16150.68 | K16: =+J16/1500 -> 10.76712 | L16: =+I16/0.0185*0.000318 -> 27.761709 | N16: =+M16*3.276 -> 0 | O16: =+N16/0.0185*0.185 -> 0 | P16: =+O16/1500 -> 0 | Q16: =+N16/0.0185*0.000318 -> 0 | S16: =+R16*3.276 -> 0 | T16: =+S16/0.0185*0.185 -> 0 | U16: =+T16/1500 -> 0 | V16: =+S16/0.0185*0.000318 -> 0
A17: =+$A16 -> 46205 | B17: QG02703 | D17: =+C17*3.875 -> 0 | E17: =+D17/0.0125*0.125 -> 0 | F17: =+E17/1500 -> 0 | G17: =+D17/0.0125*0.000318 -> 0 | H17: 416 | I17: =+H17*3.276 -> 1362.816 | J17: =+I17/0.0185*0.185 -> 13628.16 | K17: =+J17/1500 -> 9.08544 | L17: =+I17/0.0185*0.000318 -> 23.425702 | N17: =+M17*3.276 -> 0 | O17: =+N17/0.0185*0.185 -> 0 | P17: =+O17/1500 -> 0 | Q17: =+N17/0.0185*0.000318 -> 0 | S17: =+R17*3.276 -> 0 | T17: =+S17/0.0185*0.185 -> 0 | U17: =+T17/1500 -> 0 | V17: =+S17/0.0185*0.000318 -> 0
A18: =+$A17 -> 46205 | B18: QG02704 | D18: =+C18*3.875 -> 0 | E18: =+D18/0.0125*0.125 -> 0 | F18: =+E18/1500 -> 0 | G18: =+D18/0.0125*0.000318 -> 0 | H18: 503 | I18: =+H18*3.276 -> 1647.828 | J18: =+I18/0.0185*0.185 -> 16478.28 | K18: =+J18/1500 -> 10.98552 | L18: =+I18/0.0185*0.000318 -> 28.324827 | N18: =+M18*3.276 -> 0 | O18: =+N18/0.0185*0.185 -> 0 | P18: =+O18/1500 -> 0 | Q18: =+N18/0.0185*0.000318 -> 0 | S18: =+R18*3.276 -> 0 | T18: =+S18/0.0185*0.185 -> 0 | U18: =+T18/1500 -> 0 | V18: =+S18/0.0185*0.000318 -> 0
A19: =+$A18 -> 46205 | B19: QG02705 | D19: =+C19*3.875 -> 0 | E19: =+D19/0.0125*0.125 -> 0 | F19: =+E19/1500 -> 0 | G19: =+D19/0.0125*0.000318 -> 0 | H19: 519 | I19: =+H19*3.276 -> 1700.244 | J19: =+I19/0.0185*0.185 -> 17002.44 | K19: =+J19/1500 -> 11.33496 | L19: =+I19/0.0185*0.000318 -> 29.225816 | N19: =+M19*3.276 -> 0 | O19: =+N19/0.0185*0.185 -> 0 | P19: =+O19/1500 -> 0 | Q19: =+N19/0.0185*0.000318 -> 0 | S19: =+R19*3.276 -> 0 | T19: =+S19/0.0185*0.185 -> 0 | U19: =+T19/1500 -> 0 | V19: =+S19/0.0185*0.000318 -> 0
A20: =+$A19 -> 46205 | B20: QG02706 | D20: =+C20*3.875 -> 0 | E20: =+D20/0.0125*0.125 -> 0 | F20: =+E20/1500 -> 0 | G20: =+D20/0.0125*0.000318 -> 0 | H20: 474 | I20: =+H20*3.276 -> 1552.824 | J20: =+I20/0.0185*0.185 -> 15528.24 | K20: =+J20/1500 -> 10.35216 | L20: =+I20/0.0185*0.000318 -> 26.691786 | N20: =+M20*3.276 -> 0 | O20: =+N20/0.0185*0.185 -> 0 | P20: =+O20/1500 -> 0 | Q20: =+N20/0.0185*0.000318 -> 0 | S20: =+R20*3.276 -> 0 | T20: =+S20/0.0185*0.185 -> 0 | U20: =+T20/1500 -> 0 | V20: =+S20/0.0185*0.000318 -> 0
A21: =+$A20 -> 46205 | B21: QG02707 | D21: =+C21*3.875 -> 0 | E21: =+D21/0.0125*0.125 -> 0 | F21: =+E21/1500 -> 0 | G21: =+D21/0.0125*0.000318 -> 0 | H21: 557 | I21: =+H21*3.276 -> 1824.732 | J21: =+I21/0.0185*0.185 -> 18247.32 | K21: =+J21/1500 -> 12.16488 | L21: =+I21/0.0185*0.000318 -> 31.365664 | N21: =+M21*3.276 -> 0 | O21: =+N21/0.0185*0.185 -> 0 | P21: =+O21/1500 -> 0 | Q21: =+N21/0.0185*0.000318 -> 0 | S21: =+R21*3.276 -> 0 | T21: =+S21/0.0185*0.185 -> 0 | U21: =+T21/1500 -> 0 | V21: =+S21/0.0185*0.000318 -> 0
A22: =+$A21 -> 46205 | B22: QG02708 | D22: =+C22*3.875 -> 0 | E22: =+D22/0.0125*0.125 -> 0 | F22: =+E22/1500 -> 0 | G22: =+D22/0.0125*0.000318 -> 0 | H22: 586 | I22: =+H22*3.276 -> 1919.736 | J22: =+I22/0.0185*0.185 -> 19197.36 | K22: =+J22/1500 -> 12.79824 | L22: =+I22/0.0185*0.000318 -> 32.998705 | N22: =+M22*3.276 -> 0 | O22: =+N22/0.0185*0.185 -> 0 | P22: =+O22/1500 -> 0 | Q22: =+N22/0.0185*0.000318 -> 0 | S22: =+R22*3.276 -> 0 | T22: =+S22/0.0185*0.185 -> 0 | U22: =+T22/1500 -> 0 | V22: =+S22/0.0185*0.000318 -> 0
A23: =+$A22 -> 46205 | B23: QG02709 | D23: =+C23*3.875 -> 0 | E23: =+D23/0.0125*0.125 -> 0 | F23: =+E23/1500 -> 0 | G23: =+D23/0.0125*0.000318 -> 0 | H23: 393 | I23: =+H23*3.276 -> 1287.468 | J23: =+I23/0.0185*0.185 -> 12874.68 | K23: =+J23/1500 -> 8.58312 | L23: =+I23/0.0185*0.000318 -> 22.130531 | N23: =+M23*3.276 -> 0 | O23: =+N23/0.0185*0.185 -> 0 | P23: =+O23/1500 -> 0 | Q23: =+N23/0.0185*0.000318 -> 0 | S23: =+R23*3.276 -> 0 | T23: =+S23/0.0185*0.185 -> 0 | U23: =+T23/1500 -> 0 | V23: =+S23/0.0185*0.000318 -> 0
A24: =+$A23 -> 46205 | D24: =+C24*3.875 -> 0 | E24: =+D24/0.0125*0.125 -> 0 | F24: =+E24/1500 -> 0 | G24: =+D24/0.0125*0.000318 -> 0 | I24: =+H24*3.276 -> 0 | J24: =+I24/0.0185*0.185 -> 0 | K24: =+J24/1500 -> 0 | L24: =+I24/0.0185*0.000318 -> 0 | N24: =+M24*3.276 -> 0 | O24: =+N24/0.0185*0.185 -> 0 | P24: =+O24/1500 -> 0 | Q24: =+N24/0.0185*0.000318 -> 0 | S24: =+R24*3.276 -> 0 | T24: =+S24/0.0185*0.185 -> 0 | U24: =+T24/1500 -> 0 | V24: =+S24/0.0185*0.000318 -> 0
B25: TOTAL | C25: =SUM(C15:C24) -> 0 | D25: =+C25*3.875 -> 0 | E25: =SUM(E15:E24) -> 0 | F25: =SUM(F15:F24) -> 0 | G25: =SUM(G15:G24) -> 0 | H25: =SUM(H15:H24) -> 4410 | I25: =+H25*3.276 -> 14447.16 | J25: =SUM(J15:J24) -> 144471.6 | K25: =SUM(K15:K24) -> 96.3144 | L25: =SUM(L15:L24) -> 248.33497 | M25: =SUM(M15:M24) -> 0 | N25: =+M25*3.276 -> 0 | O25: =SUM(O15:O24) -> 0 | P25: =SUM(P15:P24) -> 0 | Q25: =SUM(Q15:Q24) -> 0 | R25: =SUM(R15:R24) -> 0 | S25: =+R25*3.276 -> 0 | T25: =SUM(T15:T24) -> 0 | U25: =SUM(U15:U24) -> 0 | V25: =SUM(V15:V24) -> 0
A26: =+A15+1 -> 46206 | B26: QG03701 | D26: =+C26*3.875 -> 0 | E26: =+D26/0.0125*0.125 -> 0 | F26: =+E26/1500 -> 0 | G26: =+D26/0.0125*0.000318 -> 0 | H26: 521 | I26: =+H26*3.276 -> 1706.796 | J26: =+I26/0.0185*0.185 -> 17067.96 | K26: =+J26/1500 -> 11.37864 | L26: =+I26/0.0185*0.000318 -> 29.338439 | N26: =+M26*3.276 -> 0 | O26: =+N26/0.0185*0.185 -> 0 | P26: =+O26/1500 -> 0 | Q26: =+N26/0.0185*0.000318 -> 0 | S26: =+R26*3.276 -> 0 | T26: =+S26/0.0185*0.185 -> 0 | U26: =+T26/1500 -> 0 | V26: =+S26/0.0185*0.000318 -> 0 | X26: =+W26*2.4 -> 0 | Z26: =IFERROR((D26/'REKAPAN OKEY AYAM'!$AC6),"-") -> - | AA26: =IFERROR((I26/'REKAPAN CHAMP AYAM'!$AC6),"-") -> 0.126338 | AB26: =IFERROR((N26/'REKAPAN CHAMP SAPI'!AC6),"-") -> - | AC26: =IFERROR((S26/'REKAPAN CHAMP OTAK-OTAK'!AC6),"-") -> - | AD26: =IFERROR((X26/'REKAPAN FIESTA'!AC6),"-") -> - | AF26: =IFERROR(((D26/0.0125*0.125)/F26),"-") -> - | AG26: =IFERROR(((D26/0.0125*0.000318)/#REF!),"-") -> - | AH26: =IFERROR(((I26/0.0185*0.185)/K26),"-") -> 1500 | AI26: =IFERROR(((I26/0.0185*0.000318)/#REF!),"-") -> - | AJ26: =IFERROR(((N26/0.0185*0.185)/P26),"-") -> - | AK26: =IFERROR(((N26/0.0185*0.000318)/#REF!),"-") -> - | AL26: =IFERROR(((S26/0.0185*0.185)/U26),"-") -> - | AM26: =IFERROR(((S26/0.0185*0.000318)/#REF!),"-") -> - | AQ26: =IFERROR(('REKAPAN OKEY AYAM'!$AD6),"-") -> - | AR26: =IFERROR(('REKAPAN CHAMP AYAM'!$AD6),"-") -> 1.0099765 | AS26: =IFERROR(('REKAPAN CHAMP SAPI'!$AD6),"-") -> - | AT26: =IFERROR(('REKAPAN CHAMP OTAK-OTAK'!$AD6),"-") -> - | AU26: =IFERROR(('REKAPAN FIESTA'!$AD6),"-") -> -
A27: =+$A26 -> 46206 | B27: QG03702 | D27: =+C27*3.875 -> 0 | E27: =+D27/0.0125*0.125 -> 0 | F27: =+E27/1500 -> 0 | G27: =+D27/0.0125*0.000318 -> 0 | H27: 527 | I27: =+H27*3.276 -> 1726.452 | J27: =+I27/0.0185*0.185 -> 17264.52 | K27: =+J27/1500 -> 11.50968 | L27: =+I27/0.0185*0.000318 -> 29.67631 | N27: =+M27*3.276 -> 0 | O27: =+N27/0.0185*0.185 -> 0 | P27: =+O27/1500 -> 0 | Q27: =+N27/0.0185*0.000318 -> 0 | S27: =+R27*3.276 -> 0 | T27: =+S27/0.0185*0.185 -> 0 | U27: =+T27/1500 -> 0 | V27: =+S27/0.0185*0.000318 -> 0
A28: =+$A27 -> 46206 | B28: QG03703 | D28: =+C28*3.875 -> 0 | E28: =+D28/0.0125*0.125 -> 0 | F28: =+E28/1500 -> 0 | G28: =+D28/0.0125*0.000318 -> 0 | H28: 485 | I28: =+H28*3.276 -> 1588.86 | J28: =+I28/0.0185*0.185 -> 15888.6 | K28: =+J28/1500 -> 10.5924 | L28: =+I28/0.0185*0.000318 -> 27.311215 | N28: =+M28*3.276 -> 0 | O28: =+N28/0.0185*0.185 -> 0 | P28: =+O28/1500 -> 0 | Q28: =+N28/0.0185*0.000318 -> 0 | S28: =+R28*3.276 -> 0 | T28: =+S28/0.0185*0.185 -> 0 | U28: =+T28/1500 -> 0 | V28: =+S28/0.0185*0.000318 -> 0
A29: =+$A28 -> 46206 | B29: QG03704 | D29: =+C29*3.875 -> 0 | E29: =+D29/0.0125*0.125 -> 0 | F29: =+E29/1500 -> 0 | G29: =+D29/0.0125*0.000318 -> 0 | H29: 534 | I29: =+H29*3.276 -> 1749.384 | J29: =+I29/0.0185*0.185 -> 17493.84 | K29: =+J29/1500 -> 11.66256 | L29: =+I29/0.0185*0.000318 -> 30.070493 | N29: =+M29*3.276 -> 0 | O29: =+N29/0.0185*0.185 -> 0 | P29: =+O29/1500 -> 0 | Q29: =+N29/0.0185*0.000318 -> 0 | S29: =+R29*3.276 -> 0 | T29: =+S29/0.0185*0.185 -> 0 | U29: =+T29/1500 -> 0 | V29: =+S29/0.0185*0.000318 -> 0
A30: =+$A29 -> 46206 | B30: QG03705 | D30: =+C30*3.875 -> 0 | E30: =+D30/0.0125*0.125 -> 0 | F30: =+E30/1500 -> 0 | G30: =+D30/0.0125*0.000318 -> 0 | H30: 587 | I30: =+H30*3.276 -> 1923.012 | J30: =+I30/0.0185*0.185 -> 19230.12 | K30: =+J30/1500 -> 12.82008 | L30: =+I30/0.0185*0.000318 -> 33.055017 | N30: =+M30*3.276 -> 0 | O30: =+N30/0.0185*0.185 -> 0 | P30: =+O30/1500 -> 0 | Q30: =+N30/0.0185*0.000318 -> 0 | S30: =+R30*3.276 -> 0 | T30: =+S30/0.0185*0.185 -> 0 | U30: =+T30/1500 -> 0 | V30: =+S30/0.0185*0.000318 -> 0
A31: =+$A30 -> 46206 | B31: QG03706 | D31: =+C31*3.875 -> 0 | E31: =+D31/0.0125*0.125 -> 0 | F31: =+E31/1500 -> 0 | G31: =+D31/0.0125*0.000318 -> 0 | H31: 517 | I31: =+H31*3.276 -> 1693.692 | J31: =+I31/0.0185*0.185 -> 16936.92 | K31: =+J31/1500 -> 11.29128 | L31: =+I31/0.0185*0.000318 -> 29.113192 | N31: =+M31*3.276 -> 0 | O31: =+N31/0.0185*0.185 -> 0 | P31: =+O31/1500 -> 0 | Q31: =+N31/0.0185*0.000318 -> 0 | S31: =+R31*3.276 -> 0 | T31: =+S31/0.0185*0.185 -> 0 | U31: =+T31/1500 -> 0 | V31: =+S31/0.0185*0.000318 -> 0
A32: =+$A31 -> 46206 | B32: QG03707 | D32: =+C32*3.875 -> 0 | E32: =+D32/0.0125*0.125 -> 0 | F32: =+E32/1500 -> 0 | G32: =+D32/0.0125*0.000318 -> 0 | H32: 685 | I32: =+H32*3.276 -> 2244.06 | J32: =+I32/0.0185*0.185 -> 22440.6 | K32: =+J32/1500 -> 14.9604 | L32: =+I32/0.0185*0.000318 -> 38.573572 | N32: =+M32*3.276 -> 0 | O32: =+N32/0.0185*0.185 -> 0 | P32: =+O32/1500 -> 0 | Q32: =+N32/0.0185*0.000318 -> 0 | S32: =+R32*3.276 -> 0 | T32: =+S32/0.0185*0.185 -> 0 | U32: =+T32/1500 -> 0 | V32: =+S32/0.0185*0.000318 -> 0
A33: =+$A32 -> 46206 | B33: QG03708 | D33: =+C33*3.875 -> 0 | E33: =+D33/0.0125*0.125 -> 0 | F33: =+E33/1500 -> 0 | G33: =+D33/0.0125*0.000318 -> 0 | H33: 465 | I33: =+H33*3.276 -> 1523.34 | J33: =+I33/0.0185*0.185 -> 15233.4 | K33: =+J33/1500 -> 10.1556 | L33: =+I33/0.0185*0.000318 -> 26.184979 | N33: =+M33*3.276 -> 0 | O33: =+N33/0.0185*0.185 -> 0 | P33: =+O33/1500 -> 0 | Q33: =+N33/0.0185*0.000318 -> 0 | S33: =+R33*3.276 -> 0 | T33: =+S33/0.0185*0.185 -> 0 | U33: =+T33/1500 -> 0 | V33: =+S33/0.0185*0.000318 -> 0
A34: =+$A33 -> 46206 | D34: =+C34*3.875 -> 0 | E34: =+D34/0.0125*0.125 -> 0 | F34: =+E34/1500 -> 0 | G34: =+D34/0.0125*0.000318 -> 0 | I34: =+H34*3.276 -> 0 | J34: =+I34/0.0185*0.185 -> 0 | K34: =+J34/1500 -> 0 | L34: =+I34/0.0185*0.000318 -> 0 | N34: =+M34*3.276 -> 0 | O34: =+N34/0.0185*0.185 -> 0 | P34: =+O34/1500 -> 0 | Q34: =+N34/0.0185*0.000318 -> 0 | S34: =+R34*3.276 -> 0 | T34: =+S34/0.0185*0.185 -> 0 | U34: =+T34/1500 -> 0 | V34: =+S34/0.0185*0.000318 -> 0
A35: =+$A34 -> 46206 | D35: =+C35*3.875 -> 0 | E35: =+D35/0.0125*0.125 -> 0 | F35: =+E35/1500 -> 0 | G35: =+D35/0.0125*0.000318 -> 0 | I35: =+H35*3.276 -> 0 | J35: =+I35/0.0185*0.185 -> 0 | K35: =+J35/1500 -> 0 | L35: =+I35/0.0185*0.000318 -> 0 | N35: =+M35*3.276 -> 0 | O35: =+N35/0.0185*0.185 -> 0 | P35: =+O35/1500 -> 0 | Q35: =+N35/0.0185*0.000318 -> 0 | S35: =+R35*3.276 -> 0 | T35: =+S35/0.0185*0.185 -> 0 | U35: =+T35/1500 -> 0 | V35: =+S35/0.0185*0.000318 -> 0
B36: TOTAL | C36: =SUM(C26:C35) -> 0 | D36: =+C36*3.875 -> 0 | E36: =SUM(E26:E35) -> 0 | F36: =SUM(F26:F35) -> 0 | G36: =SUM(G26:G35) -> 0 | H36: =SUM(H26:H35) -> 4321 | I36: =+H36*3.276 -> 14155.596 | J36: =SUM(J26:J35) -> 141555.96 | K36: =SUM(K26:K35) -> 94.37064 | L36: =SUM(L26:L35) -> 243.32322 | M36: =SUM(M26:M35) -> 0 | N36: =+M36*3.276 -> 0 | O36: =SUM(O26:O35) -> 0 | P36: =SUM(P26:P35) -> 0 | Q36: =SUM(Q26:Q35) -> 0 | R36: =SUM(R26:R35) -> 0 | S36: =+R36*3.276 -> 0 | T36: =SUM(T26:T35) -> 0 | U36: =SUM(U26:U35) -> 0 | V36: =SUM(V26:V35) -> 0
A37: =+A26+1 -> 46207 | D37: =+C37*3.875 -> 0 | E37: =+D37/0.0125*0.125 -> 0 | F37: =+E37/1500 -> 0 | G37: =+D37/0.0125*0.000318 -> 0 | I37: =+H37*3.276 -> 0 | J37: =+I37/0.0185*0.185 -> 0 | K37: =+J37/1500 -> 0 | L37: =+I37/0.0185*0.000318 -> 0 | N37: =+M37*3.276 -> 0 | O37: =+N37/0.0185*0.185 -> 0 | P37: =+O37/1500 -> 0 | Q37: =+N37/0.0185*0.000318 -> 0 | S37: =+R37*3.276 -> 0 | T37: =+S37/0.0185*0.185 -> 0 | U37: =+T37/1500 -> 0 | V37: =+S37/0.0185*0.000318 -> 0 | X37: =+W37*2.4 -> 0 | Z37: =IFERROR((D37/'REKAPAN OKEY AYAM'!$AC7),"-") -> - | AA37: =IFERROR((I37/'REKAPAN CHAMP AYAM'!$AC7),"-") -> - | AB37: =IFERROR((N37/'REKAPAN CHAMP SAPI'!AC7),"-") -> - | AC37: =IFERROR((S37/'REKAPAN CHAMP OTAK-OTAK'!AC7),"-") -> - | AD37: =IFERROR((X37/'REKAPAN FIESTA'!AC7),"-") -> - | AF37: =IFERROR(((D37/0.0125*0.125)/F37),"-") -> - | AG37: =IFERROR(((D37/0.0125*0.000318)/#REF!),"-") -> - | AH37: =IFERROR(((I37/0.0185*0.185)/K37),"-") -> - | AI37: =IFERROR(((I37/0.0185*0.000318)/#REF!),"-") -> - | AJ37: =IFERROR(((N37/0.0185*0.185)/P37),"-") -> - | AK37: =IFERROR(((N37/0.0185*0.000318)/#REF!),"-") -> - | AL37: =IFERROR(((S37/0.0185*0.185)/U37),"-") -> - | AM37: =IFERROR(((S37/0.0185*0.000318)/#REF!),"-") -> - | AQ37: =IFERROR(('REKAPAN OKEY AYAM'!$AD7),"-") -> - | AR37: =IFERROR(('REKAPAN CHAMP AYAM'!$AD7),"-") -> - | AS37: =IFERROR(('REKAPAN CHAMP SAPI'!$AD7),"-") -> - | AT37: =IFERROR(('REKAPAN CHAMP OTAK-OTAK'!$AD7),"-") -> - | AU37: =IFERROR(('REKAPAN FIESTA'!$AD7),"-") -> -
A38: =+$A37 -> 46207 | D38: =+C38*3.875 -> 0 | E38: =+D38/0.0125*0.125 -> 0 | F38: =+E38/1500 -> 0 | G38: =+D38/0.0125*0.000318 -> 0 | I38: =+H38*3.276 -> 0 | J38: =+I38/0.0185*0.185 -> 0 | K38: =+J38/1500 -> 0 | L38: =+I38/0.0185*0.000318 -> 0 | N38: =+M38*3.276 -> 0 | O38: =+N38/0.0185*0.185 -> 0 | P38: =+O38/1500 -> 0 | Q38: =+N38/0.0185*0.000318 -> 0 | S38: =+R38*3.276 -> 0 | T38: =+S38/0.0185*0.185 -> 0 | U38: =+T38/1500 -> 0 | V38: =+S38/0.0185*0.000318 -> 0
A39: =+$A38 -> 46207 | D39: =+C39*3.875 -> 0 | E39: =+D39/0.0125*0.125 -> 0 | F39: =+E39/1500 -> 0 | G39: =+D39/0.0125*0.000318 -> 0 | I39: =+H39*3.276 -> 0 | J39: =+I39/0.0185*0.185 -> 0 | K39: =+J39/1500 -> 0 | L39: =+I39/0.0185*0.000318 -> 0 | N39: =+M39*3.276 -> 0 | O39: =+N39/0.0185*0.185 -> 0 | P39: =+O39/1500 -> 0 | Q39: =+N39/0.0185*0.000318 -> 0 | S39: =+R39*3.276 -> 0 | T39: =+S39/0.0185*0.185 -> 0 | U39: =+T39/1500 -> 0 | V39: =+S39/0.0185*0.000318 -> 0
A40: =+$A39 -> 46207 | D40: =+C40*3.875 -> 0 | E40: =+D40/0.0125*0.125 -> 0 | F40: =+E40/1500 -> 0 | G40: =+D40/0.0125*0.000318 -> 0 | I40: =+H40*3.276 -> 0 | J40: =+I40/0.0185*0.185 -> 0 | K40: =+J40/1500 -> 0 | L40: =+I40/0.0185*0.000318 -> 0 | N40: =+M40*3.276 -> 0 | O40: =+N40/0.0185*0.185 -> 0 | P40: =+O40/1500 -> 0 | Q40: =+N40/0.0185*0.000318 -> 0 | S40: =+R40*3.276 -> 0 | T40: =+S40/0.0185*0.185 -> 0 | U40: =+T40/1500 -> 0 | V40: =+S40/0.0185*0.000318 -> 0
...

Sheet Actual VS SAP
A2: OKEY
A3: TANGGAL | B3: OKEY | H3: C. AYAM | N3: C. SAPI | T3: C. OTAK2 | Z3: FIESTA | AF3: Batch | AH3: Shift
B4: Actual | D4: SAP | F4: Selisih | H4: Actual | J4: SAP | L4: Selisih | N4: Actual | P4: SAP | R4: Selisih | T4: Actual | V4: SAP | X4: Selisih | Z4: Actual | AB4: SAP | AD4: Selisih
B5: Kg | C5: Batch | D5: Kg | E5: Batch | F5: Kg | G5: Batch | H5: Kg | I5: Batch | J5: Kg | K5: Batch | L5: Kg | M5: Batch | N5: Kg | O5: Batch | P5: Kg | Q5: Batch | R5: Kg | S5: Batch | T5: Kg | U5: Batch | V5: Kg | W5: Batch | X5: Kg | Y5: Batch | Z5: Kg | AA5: Batch | AB5: Kg | AC5: Batch | AD5: Kg | AE5: Batch | AF5: Okey | AG5: Champ
A6: =+'HASIL PROD'!A4 -> 46204 | B6: =SUMIF('HASIL PROD'!$A$4:$A$343,A6,'HASIL PROD'!$D$4:$D$343) -> 10210.625 | C6: 6.5 | D6: 14000.375 | E6: 8.5 | F6: =+B6-D6 -> -3789.75 | G6: =+C6-E6 -> -2 | H6: =SUMIF('HASIL PROD'!$A$4:$A$343,A6,'HASIL PROD'!$I$4:$I$343) -> 1516.788 | I6: 1 | L6: =+H6-J6 -> 1516.788 | M6: =+I6-K6 -> 1 | N6: =SUMIF('HASIL PROD'!$A$4:$A$343,A6,'HASIL PROD'!$N$4:$N$343) -> 0 | R6: =+N6-P6 -> 0 | S6: =+O6-Q6 -> 0 | T6: =SUMIF('HASIL PROD'!$A$4:$A$343,A6,'HASIL PROD'!$S$4:$S$344) -> 0 | X6: =+T6-V6 -> 0 | Y6: =+U6-W6 -> 0 | Z6: =+'HASIL PROD'!X4 -> 0 | AD6: =+Z6-AB6 -> 0 | AE6: =+AA6-AC6 -> 0 | AF6: =+C6 -> 6.5 | AG6: =+I6+O6+U6 -> 1
A7: =+'HASIL PROD'!A15 -> 46205 | B7: =SUMIF('HASIL PROD'!$A$4:$A$343,A7,'HASIL PROD'!$D$4:$D$343) -> 0 | F7: =+B7-D7 -> 0 | G7: =+C7-E7 -> 0 | H7: =SUMIF('HASIL PROD'!$A$4:$A$343,A7,'HASIL PROD'!$I$4:$I$343) -> 14447.16 | I7: 9 | J7: 16802.604 | K7: 10 | L7: =+H7-J7 -> -2355.444 | M7: =+I7-K7 -> -1 | N7: =SUMIF('HASIL PROD'!$A$4:$A$343,A7,'HASIL PROD'!$N$4:$N$343) -> 0 | R7: =+N7-P7 -> 0 | S7: =+O7-Q7 -> 0 | T7: =SUMIF('HASIL PROD'!$A$4:$A$343,A7,'HASIL PROD'!$S$4:$S$344) -> 0 | X7: =+T7-V7 -> 0 | Y7: =+U7-W7 -> 0 | Z7: =+'HASIL PROD'!X15 -> 0 | AD7: =+Z7-AB7 -> 0 | AE7: =+AA7-AC7 -> 0 | AF7: =+C7 -> 0 | AG7: =+I7+O7+U7 -> 9
A8: =+'HASIL PROD'!A26 -> 46206 | B8: =SUMIF('HASIL PROD'!$A$4:$A$343,A8,'HASIL PROD'!$D$4:$D$343) -> 0 | F8: =+B8-D8 -> 0 | G8: =+C8-E8 -> 0 | H8: =SUMIF('HASIL PROD'!$A$4:$A$343,A8,'HASIL PROD'!$I$4:$I$343) -> 14155.596 | I8: 8 | J8: 16805.88 | K8: 10 | L8: =+H8-J8 -> -2650.284 | M8: =+I8-K8 -> -2 | N8: =SUMIF('HASIL PROD'!$A$4:$A$343,A8,'HASIL PROD'!$N$4:$N$343) -> 0 | R8: =+N8-P8 -> 0 | S8: =+O8-Q8 -> 0 | T8: =SUMIF('HASIL PROD'!$A$4:$A$343,A8,'HASIL PROD'!$S$4:$S$344) -> 0 | X8: =+T8-V8 -> 0 | Y8: =+U8-W8 -> 0 | Z8: =+'HASIL PROD'!X26 -> 0 | AD8: =+Z8-AB8 -> 0 | AE8: =+AA8-AC8 -> 0 | AF8: =+C8 -> 0 | AG8: =+I8+O8+U8 -> 8
A9: =+'HASIL PROD'!A37 -> 46207 | B9: =SUMIF('HASIL PROD'!$A$4:$A$343,A9,'HASIL PROD'!$D$4:$D$343) -> 0 | F9: =+B9-D9 -> 0 | G9: =+C9-E9 -> 0 | H9: =SUMIF('HASIL PROD'!$A$4:$A$343,A9,'HASIL PROD'!$I$4:$I$343) -> 0 | L9: =+H9-J9 -> 0 | M9: =+I9-K9 -> 0 | N9: =SUMIF('HASIL PROD'!$A$4:$A$343,A9,'HASIL PROD'!$N$4:$N$343) -> 0 | R9: =+N9-P9 -> 0 | S9: =+O9-Q9 -> 0 | T9: =SUMIF('HASIL PROD'!$A$4:$A$343,A9,'HASIL PROD'!$S$4:$S$344) -> 0 | X9: =+T9-V9 -> 0 | Y9: =+U9-W9 -> 0 | Z9: =+'HASIL PROD'!X37 -> 0 | AD9: =+Z9-AB9 -> 0 | AE9: =+AA9-AC9 -> 0 | AF9: =+C9 -> 0 | AG9: =+I9+O9+U9 -> 0
A10: =+'HASIL PROD'!A48 -> 46208 | B10: =SUMIF('HASIL PROD'!$A$4:$A$343,A10,'HASIL PROD'!$D$4:$D$343) -> 0 | F10: =+B10-D10 -> 0 | G10: =+C10-E10 -> 0 | H10: =SUMIF('HASIL PROD'!$A$4:$A$343,A10,'HASIL PROD'!$I$4:$I$343) -> 0 | L10: =+H10-J10 -> 0 | M10: =+I10-K10 -> 0 | N10: =SUMIF('HASIL PROD'!$A$4:$A$343,A10,'HASIL PROD'!$N$4:$N$343) -> 0 | R10: =+N10-P10 -> 0 | S10: =+O10-Q10 -> 0 | T10: =SUMIF('HASIL PROD'!$A$4:$A$343,A10,'HASIL PROD'!$S$4:$S$344) -> 0 | X10: =+T10-V10 -> 0 | Y10: =+U10-W10 -> 0 | Z10: =+'HASIL PROD'!X48 -> 0 | AD10: =+Z10-AB10 -> 0 | AE10: =+AA10-AC10 -> 0 | AF10: =+C10 -> 0 | AG10: =+I10+O10+U10 -> 0
A11: =+'HASIL PROD'!A59 -> 46209 | B11: =SUMIF('HASIL PROD'!$A$4:$A$343,A11,'HASIL PROD'!$D$4:$D$343) -> 1495.75 | C11: 1 | F11: =+B11-D11 -> 1495.75 | G11: =+C11-E11 -> 1 | H11: =SUMIF('HASIL PROD'!$A$4:$A$343,A11,'HASIL PROD'!$I$4:$I$343) -> 0 | L11: =+H11-J11 -> 0 | M11: =+I11-K11 -> 0 | N11: =SUMIF('HASIL PROD'!$A$4:$A$343,A11,'HASIL PROD'!$N$4:$N$343) -> 0 | R11: =+N11-P11 -> 0 | S11: =+O11-Q11 -> 0 | T11: =SUMIF('HASIL PROD'!$A$4:$A$343,A11,'HASIL PROD'!$S$4:$S$344) -> 0 | X11: =+T11-V11 -> 0 | Y11: =+U11-W11 -> 0 | Z11: =+'HASIL PROD'!X59 -> 0 | AD11: =+Z11-AB11 -> 0 | AE11: =+AA11-AC11 -> 0 | AF11: =+C11 -> 1 | AG11: =+I11+O11+U11 -> 0
A12: =+'HASIL PROD'!A70 -> 46210 | B12: =SUMIF('HASIL PROD'!$A$4:$A$343,A12,'HASIL PROD'!$D$4:$D$343) -> 12775.875 | C12: 8 | D12: 14004.25 | E12: 8.5 | F12: =+B12-D12 -> -1228.375 | G12: =+C12-E12 -> -0.5 | H12: =SUMIF('HASIL PROD'!$A$4:$A$343,A12,'HASIL PROD'!$I$4:$I$343) -> 0 | L12: =+H12-J12 -> 0 | M12: =+I12-K12 -> 0 | N12: =SUMIF('HASIL PROD'!$A$4:$A$343,A12,'HASIL PROD'!$N$4:$N$343) -> 0 | R12: =+N12-P12 -> 0 | S12: =+O12-Q12 -> 0 | T12: =SUMIF('HASIL PROD'!$A$4:$A$343,A12,'HASIL PROD'!$S$4:$S$344) -> 0 | X12: =+T12-V12 -> 0 | Y12: =+U12-W12 -> 0 | Z12: =+'HASIL PROD'!X70 -> 0 | AD12: =+Z12-AB12 -> 0 | AE12: =+AA12-AC12 -> 0 | AF12: =+C12 -> 8 | AG12: =+I12+O12+U12 -> 0
A13: =+'HASIL PROD'!A81 -> 46211 | B13: =SUMIF('HASIL PROD'!$A$4:$A$343,A13,'HASIL PROD'!$D$4:$D$343) -> 14426.625 | C13: 9 | D13: 14008.125 | E13: 8.5 | F13: =+B13-D13 -> 418.5 | G13: =+C13-E13 -> 0.5 | H13: =SUMIF('HASIL PROD'!$A$4:$A$343,A13,'HASIL PROD'!$I$4:$I$343) -> 0 | L13: =+H13-J13 -> 0 | M13: =+I13-K13 -> 0 | N13: =SUMIF('HASIL PROD'!$A$4:$A$343,A13,'HASIL PROD'!$N$4:$N$343) -> 0 | R13: =+N13-P13 -> 0 | S13: =+O13-Q13 -> 0 | T13: =SUMIF('HASIL PROD'!$A$4:$A$343,A13,'HASIL PROD'!$S$4:$S$344) -> 0 | X13: =+T13-V13 -> 0 | Y13: =+U13-W13 -> 0 | Z13: =+'HASIL PROD'!X81 -> 0 | AD13: =+Z13-AB13 -> 0 | AE13: =+AA13-AC13 -> 0 | AF13: =+C13 -> 9 | AG13: =+I13+O13+U13 -> 0
A14: =+'HASIL PROD'!A92 -> 46212 | B14: =SUMIF('HASIL PROD'!$A$4:$A$343,A14,'HASIL PROD'!$D$4:$D$343) -> 15209.375 | C14: 9 | D14: 14012 | E14: 8.5 | F14: =+B14-D14 -> 1197.375 | G14: =+C14-E14 -> 0.5 | H14: =SUMIF('HASIL PROD'!$A$4:$A$343,A14,'HASIL PROD'!$I$4:$I$343) -> 0 | L14: =+H14-J14 -> 0 | M14: =+I14-K14 -> 0 | N14: =SUMIF('HASIL PROD'!$A$4:$A$343,A14,'HASIL PROD'!$N$4:$N$343) -> 0 | R14: =+N14-P14 -> 0 | S14: =+O14-Q14 -> 0 | T14: =SUMIF('HASIL PROD'!$A$4:$A$343,A14,'HASIL PROD'!$S$4:$S$344) -> 0 | X14: =+T14-V14 -> 0 | Y14: =+U14-W14 -> 0 | Z14: =+'HASIL PROD'!X92 -> 0 | AD14: =+Z14-AB14 -> 0 | AE14: =+AA14-AC14 -> 0 | AF14: =+C14 -> 9 | AG14: =+I14+O14+U14 -> 0
A15: =+'HASIL PROD'!A103 -> 46213 | B15: =SUMIF('HASIL PROD'!$A$4:$A$343,A15,'HASIL PROD'!$D$4:$D$343) -> 14418.875 | C15: 9 | D15: 14015.875 | E15: 8.5 | F15: =+B15-D15 -> 403 | G15: =+C15-E15 -> 0.5 | H15: =SUMIF('HASIL PROD'!$A$4:$A$343,A15,'HASIL PROD'!$I$4:$I$343) -> 0 | L15: =+H15-J15 -> 0 | M15: =+I15-K15 -> 0 | N15: =SUMIF('HASIL PROD'!$A$4:$A$343,A15,'HASIL PROD'!$N$4:$N$343) -> 0 | R15: =+N15-P15 -> 0 | S15: =+O15-Q15 -> 0 | T15: =SUMIF('HASIL PROD'!$A$4:$A$343,A15,'HASIL PROD'!$S$4:$S$344) -> 0 | X15: =+T15-V15 -> 0 | Y15: =+U15-W15 -> 0 | Z15: =+'HASIL PROD'!X103 -> 0 | AD15: =+Z15-AB15 -> 0 | AE15: =+AA15-AC15 -> 0 | AF15: =+C15 -> 9 | AG15: =+I15+O15+U15 -> 0
A16: =+'HASIL PROD'!A114 -> 46214 | B16: =SUMIF('HASIL PROD'!$A$4:$A$343,A16,'HASIL PROD'!$D$4:$D$343) -> 0 | F16: =+B16-D16 -> 0 | G16: =+C16-E16 -> 0 | H16: =SUMIF('HASIL PROD'!$A$4:$A$343,A16,'HASIL PROD'!$I$4:$I$343) -> 0 | L16: =+H16-J16 -> 0 | M16: =+I16-K16 -> 0 | N16: =SUMIF('HASIL PROD'!$A$4:$A$343,A16,'HASIL PROD'!$N$4:$N$343) -> 0 | R16: =+N16-P16 -> 0 | S16: =+O16-Q16 -> 0 | T16: =SUMIF('HASIL PROD'!$A$4:$A$343,A16,'HASIL PROD'!$S$4:$S$344) -> 0 | X16: =+T16-V16 -> 0 | Y16: =+U16-W16 -> 0 | Z16: =+'HASIL PROD'!X114 -> 0 | AD16: =+Z16-AB16 -> 0 | AE16: =+AA16-AC16 -> 0 | AF16: =+C16 -> 0 | AG16: =+I16+O16+U16 -> 0
A17: =+'HASIL PROD'!A125 -> 46215 | B17: =SUMIF('HASIL PROD'!$A$4:$A$343,A17,'HASIL PROD'!$D$4:$D$343) -> 0 | F17: =+B17-D17 -> 0 | G17: =+C17-E17 -> 0 | H17: =SUMIF('HASIL PROD'!$A$4:$A$343,A17,'HASIL PROD'!$I$4:$I$343) -> 0 | L17: =+H17-J17 -> 0 | M17: =+I17-K17 -> 0 | N17: =SUMIF('HASIL PROD'!$A$4:$A$343,A17,'HASIL PROD'!$N$4:$N$343) -> 0 | R17: =+N17-P17 -> 0 | S17: =+O17-Q17 -> 0 | T17: =SUMIF('HASIL PROD'!$A$4:$A$343,A17,'HASIL PROD'!$S$4:$S$344) -> 0 | X17: =+T17-V17 -> 0 | Y17: =+U17-W17 -> 0 | Z17: =+'HASIL PROD'!X125 -> 0 | AD17: =+Z17-AB17 -> 0 | AE17: =+AA17-AC17 -> 0 | AF17: =+C17 -> 0 | AG17: =+I17+O17+U17 -> 0
A18: =+'HASIL PROD'!A136 -> 46216 | B18: =SUMIF('HASIL PROD'!$A$4:$A$343,A18,'HASIL PROD'!$D$4:$D$343) -> 0 | F18: =+B18-D18 -> 0 | G18: =+C18-E18 -> 0 | H18: =SUMIF('HASIL PROD'!$A$4:$A$343,A18,'HASIL PROD'!$I$4:$I$343) -> 1434.888 | I18: 1 | L18: =+H18-J18 -> 1434.888 | M18: =+I18-K18 -> 1 | N18: =SUMIF('HASIL PROD'!$A$4:$A$343,A18,'HASIL PROD'!$N$4:$N$343) -> 0 | R18: =+N18-P18 -> 0 | S18: =+O18-Q18 -> 0 | T18: =SUMIF('HASIL PROD'!$A$4:$A$343,A18,'HASIL PROD'!$S$4:$S$344) -> 0 | X18: =+T18-V18 -> 0 | Y18: =+U18-W18 -> 0 | Z18: =+'HASIL PROD'!X136 -> 0 | AD18: =+Z18-AB18 -> 0 | AE18: =+AA18-AC18 -> 0 | AF18: =+C18 -> 0 | AG18: =+I18+O18+U18 -> 1
A19: =+'HASIL PROD'!A147 -> 46217 | B19: =SUMIF('HASIL PROD'!$A$4:$A$343,A19,'HASIL PROD'!$D$4:$D$343) -> 0 | F19: =+B19-D19 -> 0 | G19: =+C19-E19 -> 0 | H19: =SUMIF('HASIL PROD'!$A$4:$A$343,A19,'HASIL PROD'!$I$4:$I$343) -> 15452.892 | I19: 9 | J19: 16802.604 | K19: 10 | L19: =+H19-J19 -> -1349.712 | M19: =+I19-K19 -> -1 | N19: =SUMIF('HASIL PROD'!$A$4:$A$343,A19,'HASIL PROD'!$N$4:$N$343) -> 0 | R19: =+N19-P19 -> 0 | S19: =+O19-Q19 -> 0 | T19: =SUMIF('HASIL PROD'!$A$4:$A$343,A19,'HASIL PROD'!$S$4:$S$344) -> 0 | X19: =+T19-V19 -> 0 | Y19: =+U19-W19 -> 0 | Z19: =+'HASIL PROD'!X147 -> 0 | AD19: =+Z19-AB19 -> 0 | AE19: =+AA19-AC19 -> 0 | AF19: =+C19 -> 0 | AG19: =+I19+O19+U19 -> 9
A20: =+'HASIL PROD'!A158 -> 46218 | B20: =SUMIF('HASIL PROD'!$A$4:$A$343,A20,'HASIL PROD'!$D$4:$D$343) -> 0 | F20: =+B20-D20 -> 0 | G20: =+C20-E20 -> 0 | H20: =SUMIF('HASIL PROD'!$A$4:$A$343,A20,'HASIL PROD'!$I$4:$I$343) -> 15135.12 | I20: 9 | J20: 16805.88 | K20: 10 | L20: =+H20-J20 -> -1670.76 | M20: =+I20-K20 -> -1 | N20: =SUMIF('HASIL PROD'!$A$4:$A$343,A20,'HASIL PROD'!$N$4:$N$343) -> 1470.924 | O20: 1 | R20: =+N20-P20 -> 1470.924 | S20: =+O20-Q20 -> 1 | T20: =SUMIF('HASIL PROD'!$A$4:$A$343,A20,'HASIL PROD'!$S$4:$S$344) -> 0 | X20: =+T20-V20 -> 0 | Y20: =+U20-W20 -> 0 | Z20: =+'HASIL PROD'!X158 -> 0 | AD20: =+Z20-AB20 -> 0 | AE20: =+AA20-AC20 -> 0 | AF20: =+C20 -> 0 | AG20: =+I20+O20+U20 -> 10
A21: =+'HASIL PROD'!A169 -> 46219 | B21: =SUMIF('HASIL PROD'!$A$4:$A$343,A21,'HASIL PROD'!$D$4:$D$343) -> 0 | F21: =+B21-D21 -> 0 | G21: =+C21-E21 -> 0 | H21: =SUMIF('HASIL PROD'!$A$4:$A$343,A21,'HASIL PROD'!$I$4:$I$343) -> 1513.512 | I21: 1 | L21: =+H21-J21 -> 1513.512 | M21: =+I21-K21 -> 1 | N21: =SUMIF('HASIL PROD'!$A$4:$A$343,A21,'HASIL PROD'!$N$4:$N$343) -> 16209.648 | O21: 9 | P21: 16809.156 | Q21: 9.5 | R21: =+N21-P21 -> -599.508 | S21: =+O21-Q21 -> -0.5 | T21: =SUMIF('HASIL PROD'!$A$4:$A$343,A21,'HASIL PROD'!$S$4:$S$344) -> 0 | X21: =+T21-V21 -> 0 | Y21: =+U21-W21 -> 0 | Z21: =+'HASIL PROD'!X169 -> 0 | AD21: =+Z21-AB21 -> 0 | AE21: =+AA21-AC21 -> 0 | AF21: =+C21 -> 0 | AG21: =+I21+O21+U21 -> 10
A22: =+'HASIL PROD'!A180 -> 46220 | B22: =SUMIF('HASIL PROD'!$A$4:$A$343,A22,'HASIL PROD'!$D$4:$D$343) -> 8610.25 | C22: 5 | D22: 14004.25 | E22: 8.5 | F22: =+B22-D22 -> -5394 | G22: =+C22-E22 -> -3.5 | H22: =SUMIF('HASIL PROD'!$A$4:$A$343,A22,'HASIL PROD'!$I$4:$I$343) -> 3397.212 | I22: 2 | L22: =+H22-J22 -> 3397.212 | M22: =+I22-K22 -> 2 | N22: =SUMIF('HASIL PROD'!$A$4:$A$343,A22,'HASIL PROD'!$N$4:$N$343) -> 0 | R22: =+N22-P22 -> 0 | S22: =+O22-Q22 -> 0 | T22: =SUMIF('HASIL PROD'!$A$4:$A$343,A22,'HASIL PROD'!$S$4:$S$344) -> 0 | X22: =+T22-V22 -> 0 | Y22: =+U22-W22 -> 0 | Z22: =+'HASIL PROD'!X180 -> 0 | AD22: =+Z22-AB22 -> 0 | AE22: =+AA22-AC22 -> 0 | AF22: =+C22 -> 5 | AG22: =+I22+O22+U22 -> 2
A23: =+'HASIL PROD'!A191 -> 46221 | B23: =SUMIF('HASIL PROD'!$A$4:$A$343,A23,'HASIL PROD'!$D$4:$D$343) -> 0 | F23: =+B23-D23 -> 0 | G23: =+C23-E23 -> 0 | H23: =SUMIF('HASIL PROD'!$A$4:$A$343,A23,'HASIL PROD'!$I$4:$I$343) -> 0 | L23: =+H23-J23 -> 0 | M23: =+I23-K23 -> 0 | N23: =SUMIF('HASIL PROD'!$A$4:$A$343,A23,'HASIL PROD'!$N$4:$N$343) -> 0 | R23: =+N23-P23 -> 0 | S23: =+O23-Q23 -> 0 | T23: =SUMIF('HASIL PROD'!$A$4:$A$343,A23,'HASIL PROD'!$S$4:$S$344) -> 0 | X23: =+T23-V23 -> 0 | Y23: =+U23-W23 -> 0 | Z23: =+'HASIL PROD'!X191 -> 0 | AD23: =+Z23-AB23 -> 0 | AE23: =+AA23-AC23 -> 0 | AF23: =+C23 -> 0 | AG23: =+I23+O23+U23 -> 0
A24: =+'HASIL PROD'!A202 -> 46222 | B24: =SUMIF('HASIL PROD'!$A$4:$A$343,A24,'HASIL PROD'!$D$4:$D$343) -> 0 | F24: =+B24-D24 -> 0 | G24: =+C24-E24 -> 0 | H24: =SUMIF('HASIL PROD'!$A$4:$A$343,A24,'HASIL PROD'!$I$4:$I$343) -> 0 | L24: =+H24-J24 -> 0 | M24: =+I24-K24 -> 0 | N24: =SUMIF('HASIL PROD'!$A$4:$A$343,A24,'HASIL PROD'!$N$4:$N$343) -> 0 | R24: =+N24-P24 -> 0 | S24: =+O24-Q24 -> 0 | T24: =SUMIF('HASIL PROD'!$A$4:$A$343,A24,'HASIL PROD'!$S$4:$S$344) -> 0 | X24: =+T24-V24 -> 0 | Y24: =+U24-W24 -> 0 | Z24: =+'HASIL PROD'!X202 -> 0 | AD24: =+Z24-AB24 -> 0 | AE24: =+AA24-AC24 -> 0 | AF24: =+C24 -> 0 | AG24: =+I24+O24+U24 -> 0
A25: =+'HASIL PROD'!A213 -> 46223 | B25: =SUMIF('HASIL PROD'!$A$4:$A$343,A25,'HASIL PROD'!$D$4:$D$343) -> 1553.875 | C25: 1 | F25: =+B25-D25 -> 1553.875 | G25: =+C25-E25 -> 1 | H25: =SUMIF('HASIL PROD'!$A$4:$A$343,A25,'HASIL PROD'!$I$4:$I$343) -> 0 | L25: =+H25-J25 -> 0 | M25: =+I25-K25 -> 0 | N25: =SUMIF('HASIL PROD'!$A$4:$A$343,A25,'HASIL PROD'!$N$4:$N$343) -> 0 | R25: =+N25-P25 -> 0 | S25: =+O25-Q25 -> 0 | T25: =SUMIF('HASIL PROD'!$A$4:$A$343,A25,'HASIL PROD'!$S$4:$S$344) -> 0 | X25: =+T25-V25 -> 0 | Y25: =+U25-W25 -> 0 | Z25: =+'HASIL PROD'!X213 -> 0 | AD25: =+Z25-AB25 -> 0 | AE25: =+AA25-AC25 -> 0 | AF25: =+C25 -> 1 | AG25: =+I25+O25+U25 -> 0
A26: =+'HASIL PROD'!A224 -> 46224 | B26: =SUMIF('HASIL PROD'!$A$4:$A$343,A26,'HASIL PROD'!$D$4:$D$343) -> 14666.875 | C26: 9 | D26: 14008.125 | E26: 8.5 | F26: =+B26-D26 -> 658.75 | G26: =+C26-E26 -> 0.5 | H26: =SUMIF('HASIL PROD'!$A$4:$A$343,A26,'HASIL PROD'!$I$4:$I$343) -> 0 | L26: =+H26-J26 -> 0 | M26: =+I26-K26 -> 0 | N26: =SUMIF('HASIL PROD'!$A$4:$A$343,A26,'HASIL PROD'!$N$4:$N$343) -> 0 | R26: =+N26-P26 -> 0 | S26: =+O26-Q26 -> 0 | T26: =SUMIF('HASIL PROD'!$A$4:$A$343,A26,'HASIL PROD'!$S$4:$S$344) -> 0 | X26: =+T26-V26 -> 0 | Y26: =+U26-W26 -> 0 | Z26: =+'HASIL PROD'!X224 -> 0 | AD26: =+Z26-AB26 -> 0 | AE26: =+AA26-AC26 -> 0 | AF26: =+C26 -> 9 | AG26: =+I26+O26+U26 -> 0
A27: =+'HASIL PROD'!A235 -> 46225 | B27: =SUMIF('HASIL PROD'!$A$4:$A$343,A27,'HASIL PROD'!$D$4:$D$343) -> 13674.875 | C27: 8 | D27: 14012 | E27: 8.5 | F27: =+B27-D27 -> -337.125 | G27: =+C27-E27 -> -0.5 | H27: =SUMIF('HASIL PROD'!$A$4:$A$343,A27,'HASIL PROD'!$I$4:$I$343) -> 0 | L27: =+H27-J27 -> 0 | M27: =+I27-K27 -> 0 | N27: =SUMIF('HASIL PROD'!$A$4:$A$343,A27,'HASIL PROD'!$N$4:$N$343) -> 0 | R27: =+N27-P27 -> 0 | S27: =+O27-Q27 -> 0 | T27: =SUMIF('HASIL PROD'!$A$4:$A$343,A27,'HASIL PROD'!$S$4:$S$344) -> 0 | X27: =+T27-V27 -> 0 | Y27: =+U27-W27 -> 0 | Z27: =+'HASIL PROD'!X235 -> 0 | AD27: =+Z27-AB27 -> 0 | AE27: =+AA27-AC27 -> 0 | AF27: =+C27 -> 8 | AG27: =+I27+O27+U27 -> 0
A28: =+'HASIL PROD'!A246 -> 46226 | B28: =SUMIF('HASIL PROD'!$A$4:$A$343,A28,'HASIL PROD'!$D$4:$D$343) -> 16278.875 | C28: 10 | D28: 14015.875 | E28: 8.5 | F28: =+B28-D28 -> 2263 | G28: =+C28-E28 -> 1.5 | H28: =SUMIF('HASIL PROD'!$A$4:$A$343,A28,'HASIL PROD'!$I$4:$I$343) -> 0 | L28: =+H28-J28 -> 0 | M28: =+I28-K28 -> 0 | N28: =SUMIF('HASIL PROD'!$A$4:$A$343,A28,'HASIL PROD'!$N$4:$N$343) -> 0 | R28: =+N28-P28 -> 0 | S28: =+O28-Q28 -> 0 | T28: =SUMIF('HASIL PROD'!$A$4:$A$343,A28,'HASIL PROD'!$S$4:$S$344) -> 0 | X28: =+T28-V28 -> 0 | Y28: =+U28-W28 -> 0 | Z28: =+'HASIL PROD'!X246 -> 0 | AD28: =+Z28-AB28 -> 0 | AE28: =+AA28-AC28 -> 0 | AF28: =+C28 -> 10 | AG28: =+I28+O28+U28 -> 0
A29: =+'HASIL PROD'!A257 -> 46227 | B29: =SUMIF('HASIL PROD'!$A$4:$A$343,A29,'HASIL PROD'!$D$4:$D$343) -> 14705.625 | C29: 9 | D29: =+D22 -> 14004.25 | E29: 8.5 | F29: =+B29-D29 -> 701.375 | G29: =+C29-E29 -> 0.5 | H29: =SUMIF('HASIL PROD'!$A$4:$A$343,A29,'HASIL PROD'!$I$4:$I$343) -> 0 | L29: =+H29-J29 -> 0 | M29: =+I29-K29 -> 0 | N29: =SUMIF('HASIL PROD'!$A$4:$A$343,A29,'HASIL PROD'!$N$4:$N$343) -> 0 | R29: =+N29-P29 -> 0 | S29: =+O29-Q29 -> 0 | T29: =SUMIF('HASIL PROD'!$A$4:$A$343,A29,'HASIL PROD'!$S$4:$S$344) -> 0 | X29: =+T29-V29 -> 0 | Y29: =+U29-W29 -> 0 | Z29: =+'HASIL PROD'!X257 -> 0 | AD29: =+Z29-AB29 -> 0 | AE29: =+AA29-AC29 -> 0 | AF29: =+C29 -> 9 | AG29: =+I29+O29+U29 -> 0
A30: =+'HASIL PROD'!A268 -> 46228 | B30: =SUMIF('HASIL PROD'!$A$4:$A$343,A30,'HASIL PROD'!$D$4:$D$343) -> 12741 | C30: 8 | D30: =+D29-3.875 -> 14000.375 | E30: 8.5 | F30: =+B30-D30 -> -1259.375 | G30: =+C30-E30 -> -0.5 | H30: =SUMIF('HASIL PROD'!$A$4:$A$343,A30,'HASIL PROD'!$I$4:$I$343) -> 0 | L30: =+H30-J30 -> 0 | M30: =+I30-K30 -> 0 | N30: =SUMIF('HASIL PROD'!$A$4:$A$343,A30,'HASIL PROD'!$N$4:$N$343) -> 0 | R30: =+N30-P30 -> 0 | S30: =+O30-Q30 -> 0 | T30: =SUMIF('HASIL PROD'!$A$4:$A$343,A30,'HASIL PROD'!$S$4:$S$344) -> 0 | X30: =+T30-V30 -> 0 | Y30: =+U30-W30 -> 0 | Z30: =+'HASIL PROD'!X268 -> 0 | AD30: =+Z30-AB30 -> 0 | AE30: =+AA30-AC30 -> 0 | AF30: =+C30 -> 8 | AG30: =+I30+O30+U30 -> 0
A31: =+'HASIL PROD'!A279 -> 46229 | B31: =SUMIF('HASIL PROD'!$A$4:$A$343,A31,'HASIL PROD'!$D$4:$D$343) -> 0 | F31: =+B31-D31 -> 0 | G31: =+C31-E31 -> 0 | H31: =SUMIF('HASIL PROD'!$A$4:$A$343,A31,'HASIL PROD'!$I$4:$I$343) -> 0 | L31: =+H31-J31 -> 0 | M31: =+I31-K31 -> 0 | N31: =SUMIF('HASIL PROD'!$A$4:$A$343,A31,'HASIL PROD'!$N$4:$N$343) -> 0 | R31: =+N31-P31 -> 0 | S31: =+O31-Q31 -> 0 | T31: =SUMIF('HASIL PROD'!$A$4:$A$343,A31,'HASIL PROD'!$S$4:$S$344) -> 0 | X31: =+T31-V31 -> 0 | Y31: =+U31-W31 -> 0 | Z31: =+'HASIL PROD'!X279 -> 0 | AD31: =+Z31-AB31 -> 0 | AE31: =+AA31-AC31 -> 0 | AF31: =+C31 -> 0 | AG31: =+I31+O31+U31 -> 0
A32: =+'HASIL PROD'!A290 -> 46230 | B32: =SUMIF('HASIL PROD'!$A$4:$A$343,A32,'HASIL PROD'!$D$4:$D$343) -> 0 | F32: =+B32-D32 -> 0 | G32: =+C32-E32 -> 0 | H32: =SUMIF('HASIL PROD'!$A$4:$A$343,A32,'HASIL PROD'!$I$4:$I$343) -> 0 | L32: =+H32-J32 -> 0 | M32: =+I32-K32 -> 0 | N32: =SUMIF('HASIL PROD'!$A$4:$A$343,A32,'HASIL PROD'!$N$4:$N$343) -> 0 | R32: =+N32-P32 -> 0 | S32: =+O32-Q32 -> 0 | T32: =SUMIF('HASIL PROD'!$A$4:$A$343,A32,'HASIL PROD'!$S$4:$S$344) -> 0 | X32: =+T32-V32 -> 0 | Y32: =+U32-W32 -> 0 | Z32: =+'HASIL PROD'!X290 -> 0 | AD32: =+Z32-AB32 -> 0 | AE32: =+AA32-AC32 -> 0 | AF32: =+C32 -> 0 | AG32: =+I32+O32+U32 -> 0
A33: =+'HASIL PROD'!A301 -> 46231 | B33: =SUMIF('HASIL PROD'!$A$4:$A$343,A33,'HASIL PROD'!$D$4:$D$343) -> 0 | F33: =+B33-D33 -> 0 | G33: =+C33-E33 -> 0 | H33: =SUMIF('HASIL PROD'!$A$4:$A$343,A33,'HASIL PROD'!$I$4:$I$343) -> 0 | L33: =+H33-J33 -> 0 | M33: =+I33-K33 -> 0 | N33: =SUMIF('HASIL PROD'!$A$4:$A$343,A33,'HASIL PROD'!$N$4:$N$343) -> 0 | R33: =+N33-P33 -> 0 | S33: =+O33-Q33 -> 0 | T33: =SUMIF('HASIL PROD'!$A$4:$A$343,A33,'HASIL PROD'!$S$4:$S$344) -> 0 | X33: =+T33-V33 -> 0 | Y33: =+U33-W33 -> 0 | Z33: =+'HASIL PROD'!X301 -> 0 | AD33: =+Z33-AB33 -> 0 | AE33: =+AA33-AC33 -> 0 | AF33: =+C33 -> 0 | AG33: =+I33+O33+U33 -> 0
A34: =+'HASIL PROD'!A312 -> 46232 | B34: =SUMIF('HASIL PROD'!$A$4:$A$343,A34,'HASIL PROD'!$D$4:$D$343) -> 0 | F34: =+B34-D34 -> 0 | G34: =+C34-E34 -> 0 | H34: =SUMIF('HASIL PROD'!$A$4:$A$343,A34,'HASIL PROD'!$I$4:$I$343) -> 0 | L34: =+H34-J34 -> 0 | M34: =+I34-K34 -> 0 | N34: =SUMIF('HASIL PROD'!$A$4:$A$343,A34,'HASIL PROD'!$N$4:$N$343) -> 0 | R34: =+N34-P34 -> 0 | S34: =+O34-Q34 -> 0 | T34: =SUMIF('HASIL PROD'!$A$4:$A$343,A34,'HASIL PROD'!$S$4:$S$344) -> 0 | X34: =+T34-V34 -> 0 | Y34: =+U34-W34 -> 0 | Z34: =+'HASIL PROD'!X312 -> 0 | AD34: =+Z34-AB34 -> 0 | AE34: =+AA34-AC34 -> 0 | AF34: =+C34 -> 0 | AG34: =+I34+O34+U34 -> 0
A35: =+'HASIL PROD'!A323 -> 46233 | B35: =SUMIF('HASIL PROD'!$A$4:$A$343,A35,'HASIL PROD'!$D$4:$D$343) -> 0 | F35: =+B35-D35 -> 0 | G35: =+C35-E35 -> 0 | H35: =SUMIF('HASIL PROD'!$A$4:$A$343,A35,'HASIL PROD'!$I$4:$I$343) -> 0 | L35: =+H35-J35 -> 0 | M35: =+I35-K35 -> 0 | N35: =SUMIF('HASIL PROD'!$A$4:$A$343,A35,'HASIL PROD'!$N$4:$N$343) -> 0 | R35: =+N35-P35 -> 0 | S35: =+O35-Q35 -> 0 | T35: =SUMIF('HASIL PROD'!$A$4:$A$343,A35,'HASIL PROD'!$S$4:$S$344) -> 0 | X35: =+T35-V35 -> 0 | Y35: =+U35-W35 -> 0 | Z35: =+'HASIL PROD'!X323 -> 0 | AD35: =+Z35-AB35 -> 0 | AE35: =+AA35-AC35 -> 0 | AF35: =+C35 -> 0 | AG35: =+I35+O35+U35 -> 0
A36: =+'HASIL PROD'!A334 -> 46234 | B36: =SUMIF('HASIL PROD'!$A$4:$A$343,A36,'HASIL PROD'!$D$4:$D$343) -> 0 | F36: =+B36-D36 -> 0 | G36: =+C36-E36 -> 0 | H36: =SUMIF('HASIL PROD'!$A$4:$A$343,A36,'HASIL PROD'!$I$4:$I$343) -> 0 | L36: =+H36-J36 -> 0 | M36: =+I36-K36 -> 0 | N36: =SUMIF('HASIL PROD'!$A$4:$A$343,A36,'HASIL PROD'!$N$4:$N$343) -> 0 | R36: =+N36-P36 -> 0 | S36: =+O36-Q36 -> 0 | T36: =SUMIF('HASIL PROD'!$A$4:$A$343,A36,'HASIL PROD'!$S$4:$S$344) -> 0 | X36: =+T36-V36 -> 0 | Y36: =+U36-W36 -> 0 | Z36: =+'HASIL PROD'!X334 -> 0 | AD36: =+Z36-AB36 -> 0 | AE36: =+AA36-AC36 -> 0 | AF36: =+C36 -> 0 | AG36: =+I36+O36+U36 -> 0
A38: TOTAL | B38: =SUM(B6:B36) -> 150768.5 | C38: =SUM(C6:C37) -> 92.5 | D38: =SUM(D6:D36) -> 154085.5 | E38: =SUM(E6:E37) -> 93.5 | F38: =SUM(F6:F36) -> -3317 | G38: =SUM(G6:G37) -> -1 | H38: =SUM(H6:H36) -> 67053.168 | I38: =SUM(I6:I37) -> 40 | J38: =SUM(J6:J36) -> 67216.968 | K38: =SUM(K6:K37) -> 40 | L38: =SUM(L6:L36) -> -163.8 | M38: =SUM(M6:M37) -> 0 | N38: =SUM(N6:N36) -> 17680.572 | O38: =SUM(O6:O37) -> 10 | P38: =SUM(P6:P36) -> 16809.156 | Q38: =SUM(Q6:Q37) -> 9.5 | R38: =SUM(R6:R36) -> 871.416 | S38: =SUM(S6:S37) -> 0.5 | T38: =SUM(T6:T36) -> 0 | U38: =SUM(U6:U37) -> 0 | V38: =SUM(V6:V36) -> 0 | W38: =SUM(W6:W37) -> 0 | X38: =SUM(X6:X36) -> 0 | Y38: =SUM(Y6:Y37) -> 0 | Z38: =SUM(Z6:Z36) -> 0 | AA38: =SUM(AA6:AA37) -> 0 | AB38: =SUM(AB6:AB36) -> 0 | AC38: =SUM(AC6:AC37) -> 0 | AD38: =SUM(AD6:AD36) -> 0 | AE38: =SUM(AE6:AE37) -> 0 | AF38: =SUM(AF6:AF37) -> 92.5 | AG38: =SUM(AG6:AG37) -> 50 | AH38: =SUM(AH6:AH37) -> 0 | AI38: =+AH38/3 -> 0 | AJ38: Hari | AK38: 9 hari + 2 shift
B39: =+B38-'[1]Juli''26'!$C$35 -> -1460.875 | D39: =+D38-[2]SEPTEMBER!$AN$30 -> 75364.625 | G39: =-C41 -> 0 | P39: =+P38-[2]SEPTEMBER!$AN$24 -> -8399.664 | V39: =+V38-[2]SEPTEMBER!$AN$25 -> -1729.728 | AI39: =9*3 -> 27
A40: CMO Juli'26 | B40: 154000 | C40: =+B40/1578.68 -> 97.549852 | G40: =SUM(G38:G39) -> -1 | H40: 67200 | I40: =+H40/1688.22 -> 39.805239 | J40: =+I40-I38 -> -0.19476135 | N40: 16800 | O40: =+N40/1754.712 -> 9.5742207 | T40: 1720 | U40: =+T40/1721.98 -> 0.99885016 | AA40: =+Z40/1678.06 -> 0
A41: Hutang Juni'26 | C41: =+B41/1578.68 -> 0 | I41: =+H41/1688.22 -> 0 | O41: =+N41/1754.712 -> 0 | U41: =+T41/1721.98 -> 0
A42: Over Produksi Juli'26 | C42: =+B42/1578.68 -> 0 | I42: =+H42/1688.22 -> 0 | O42: =+N42/1752.06 -> 0 | U42: =+T42/1721.98 -> 0
...

Sheet RIJECT COOKING
A1: LAPORAN RIJECT SOSIS OKEY | Y1: LAPORAN RIJECT SOSIS AYAM | AW1: LAPORAN RIJECT SOSIS SAPI | BU1: LAPORAN RIJECT SOSIS OTAK2 | CS1: LAPORAN RIJECT SOSIS FIESTA | DQ1: SUMARRY RIJECT COOKING
A2: 46204 | Y2: =+A2 -> 46204 | AW2: =+A2 -> 46204 | BU2: =+A2 -> 46204 | CS2: =+A2 -> 46204 | DQ2: =+A2 -> 46204
W3: =+(V41+[3]Keju!S41+[3]Sapi!S41+[3]Rendang!T41)/4 -> 0.0059453516 | AU3: =+(AT41+[3]Keju!AO41+[3]Sapi!AO41+[3]Rendang!AP41)/4 -> #REF! | CQ3: =+(CP41+[3]Keju!CG41+[3]Sapi!CG41+[3]Rendang!CH41)/4 -> #DIV/0! | DO3: =+(DN41+[3]Keju!DC41+[3]Sapi!DC41+[3]Rendang!DD41)/4 -> #DIV/0!
A4: TGL PRODUKSI | B4: INPUT | T4: TOTAL INPUT | U4: RM | V4: % RIJECT COOKING 0,2 % | W4: % RIJECT NON KLIP 0,02 % | Y4: TGL PRODUKSI | Z4: INPUT | AR4: TOTAL INPUT | AS4: RM | AT4: % RIJECT COOKING 0,2 % | AU4: % RIJECT NON KLIP 0,02 % | AW4: TGL PRODUKSI | AX4: INPUT | BP4: TOTAL INPUT | BQ4: RM | BR4: % RIJECT COOKING 0,2 % | BS4: % RIJECT NON KLIP 0,02 % | BU4: TGL PRODUKSI | BV4: INPUT | CN4: TOTAL INPUT | CO4: RM | CP4: % RIJECT COOKING 0,2 % | CQ4: % RIJECT NON KLIP 0,02 % | CS4: TGL PRODUKSI | CT4: INPUT | DL4: TOTAL INPUT | DM4: RM | DN4: % RIJECT COOKING 0,2 % | DO4: % RIJECT NON KLIP 0,02 % | DQ4: INPUT | EI4: TOTAL INPUT | EJ4: RM | EK4: % RIJECT COOKING 0,2 % | EL4: % RIJECT NON KLIP 0,02 %
B5: REJECT COOKING MESIN- | P5: TOTAL REJECT COOKING | Q5: Non Klip | R5: Pecah Trouble Mesin | S5: Bengkok | Z5: REJECT COOKING MESIN- | AN5: TOTAL REJECT COOKING | AO5: Non Klip | AP5: Pecah Trouble Mesin | AQ5: Bengkok | AX5: REJECT COOKING MESIN- | BL5: TOTAL REJECT COOKING | BM5: Non Klip | BN5: Pecah Trouble Mesin | BO5: Bengkok | BV5: REJECT COOKING MESIN- | CJ5: TOTAL REJECT COOKING | CK5: Non Klip | CL5: Pecah Trouble Mesin | CM5: Bengkok | CT5: REJECT COOKING MESIN- | DH5: TOTAL REJECT COOKING | DI5: Non Klip | DJ5: Pecah Trouble Mesin | DK5: Bengkok | DQ5: REJECT COOKING MESIN- | EE5: TOTAL REJECT COOKING | EF5: Non Klip | EG5: Pecah Trouble Mesin | EH5: Bengkok
B6: K1 | C6: C1 | D6: C2 | E6: C3 | F6: C4 | G6: C5 | H6: C6 | I6: Z1 | J6: Z2 | K6: Z3 | L6: Z4 | M6: Z5 | N6: Z6 | O6: Z7 | Z6: K1 | AA6: C1 | AB6: C2 | AC6: C3 | AD6: C4 | AE6: C5 | AF6: C6 | AG6: Z1 | AH6: Z2 | AI6: Z3 | AJ6: Z4 | AK6: Z5 | AL6: Z6 | AM6: Z7 | AX6: K1 | AY6: C1 | AZ6: C2 | BA6: C3 | BB6: C4 | BC6: C5 | BD6: C6 | BE6: Z1 | BF6: Z2 | BG6: Z3 | BH6: Z4 | BI6: Z5 | BJ6: Z6 | BK6: Z7 | BV6: K1 | BW6: C1 | BX6: C2 | BY6: C3 | BZ6: C4 | CA6: C5 | CB6: C6 | CC6: Z1 | CD6: Z2 | CE6: Z3 | CF6: Z4 | CG6: Z5 | CH6: Z6 | CI6: Z7 | CT6: K1 | CU6: C1 | CV6: C2 | CW6: C3 | CX6: C4 | CY6: C5 | CZ6: C6 | DA6: Z1 | DB6: Z2 | DC6: Z3 | DD6: Z4 | DE6: Z5 | DF6: Z6 | DG6: Z7 | DQ6: K1 | DR6: C1 | DS6: C2 | DT6: C3 | DU6: C4 | DV6: C5 | DW6: C6 | DX6: Z1 | DY6: Z2 | DZ6: Z3 | EA6: Z4 | EB6: Z5 | EC6: Z6 | ED6: Z7
A7: =+'ALL SORTASI'!A6 -> 46204 | B7: =4+2+1+0.4 -> 7.4 | D7: =1+1+1 -> 3 | F7: 1 | G7: =2+2+2+4+2+1+0.3 -> 13.3 | H7: =2+2+2+1+1+0.3 -> 8.3 | J7: =1+1+2+1+0.3 -> 5.3 | K7: =1+0.3 -> 1.3 | L7: 0.4 | M7: =1+1 -> 2 | N7: =1+2+1 -> 4 | O7: =1+1+1+1.5+1 -> 5.5 | P7: =SUM(B7:O7) -> 51.5 | Q7: =4+3.5+5+8+10+6+2 -> 38.5 | T7: =SUM(P7:S7) -> 90 | U7: =+'REKAPAN OKEY AYAM'!AC4 -> 10261.42 | V7: =+P7/U7 -> 0.0050187986 | W7: =+Q7/U7 -> 0.0037519174 | Y7: =+A7 -> 46204 | AB7: 1 | AC7: 1 | AD7: 1 | AE7: 1 | AH7: 1 | AI7: 1 | AL7: 1 | AN7: =SUM(Z7:AM7) -> 7 | AO7: 4 | AR7: =SUM(AN7:AQ7) -> 11 | AS7: =+'REKAPAN CHAMP AYAM'!AC4 -> 1688.72 | AT7: =+AN7/AS7 -> 0.0041451514 | AU7: =+AO7/AS7 -> 0.0023686579 | AW7: =+A7 -> 46204 | BL7: =SUM(AX7:BK7) -> 0 | BP7: =SUM(BL7:BO7) -> 0 | BQ7: =+'REKAPAN CHAMP SAPI'!AC4 -> 0 | BR7: =+BL7/BQ7 -> #DIV/0! | BS7: =+BM7/BQ7 -> #DIV/0! | BU7: =+A7 -> 46204 | CJ7: =SUM(BV7:CI7) -> 0 | CN7: =SUM(CJ7:CM7) -> 0 | CO7: =+'REKAPAN CHAMP OTAK-OTAK'!AC4 -> 0 | CP7: =+CJ7/CO7 -> #DIV/0! | CQ7: =+CK7/CO7 -> #DIV/0! | CS7: =+A7 -> 46204 | DH7: =SUM(CT7:DG7) -> 0 | DL7: =SUM(DH7:DK7) -> 0 | DM7: =+'REKAPAN CHAMP OTAK-OTAK'!AY4 -> 0 | DN7: =+DH7/DM7 -> #DIV/0! | DO7: =+DI7/DM7 -> #DIV/0! | DQ7: =+B7+Z7+AX7+BV7+CT7 -> 7.4 | DR7: =+C7+AA7+AY7+BW7+CU7 -> 0 | DS7: =+D7+AB7+AZ7+BX7+CV7 -> 4 | DT7: =+E7+AC7+BA7+BY7+CW7 -> 1 | DU7: =+F7+AD7+BB7+BZ7+CX7 -> 2 | DV7: =+G7+AE7+BC7+CA7+CY7 -> 14.3 | DW7: =+H7+AF7+BD7+CB7+CZ7 -> 8.3 | DX7: =+I7+AG7+BE7+CC7+DA7 -> 0 | ... ED7: =+O7+AM7+BK7+CI7+DG7 -> 5.5 | EE7: =SUM(DQ7:ED7) -> 58.5 | EF7: =+Q7+AO7+BM7+CK7+DI7 -> 42.5 | EG7: =+R7+AP7+BN7+CL7+DJ7 -> 0 | EH7: =+S7+AQ7+BO7+CM7+DK7 -> 0 | EI7: =SUM(EE7:EH7) -> 101 | EJ7: =+U7+AS7+BQ7+CO7+DM7 -> 11950.14 | EK7: =+EE7/EJ7 -> 0.0048953401 | EL7: =+EF7/EJ7 -> 0.0035564437
A8: =+A7+1 -> 46205 | P8: =SUM(B8:O8) -> 0 | T8: =SUM(P8:S8) -> 0 | U8: =+'REKAPAN OKEY AYAM'!AC5 -> 0 | V8: =+P8/U8 -> #DIV/0! | W8: =+Q8/U8 -> #DIV/0! | Y8: =+Y7+1 -> 46205 | AB8: =1+1+0.5+1.5+1+1 -> 6 | AC8: =1+0.5+1.5+1+1 -> 5 | AD8: 0.5 | AE8: =2+2+1+0.5 -> 5.5 | AF8: =2+1+1+0.5+0.5+2+1.5+1 -> 9.5 | AH8: =1+1+0.5+1.5+1+1 -> 6 | AI8: 1 | AJ8: =1+0.5+0.5+1.5+2 -> 5.5 | AK8: =1.5+1.5+1 -> 4 | AL8: =2+1+0.5+0.5+1.5+1.5+1 -> 8 | AM8: 1.5 | AN8: =SUM(Z8:AM8) -> 52.5 | AO8: =4+5+2.5+3+3+8+7+3 -> 35.5 | AR8: =SUM(AN8:AQ8) -> 88 | AS8: =+'REKAPAN CHAMP AYAM'!AC5 -> 15198.48 | AT8: =+AN8/AS8 -> 0.0034542928 | AU8: =+AO8/AS8 -> 0.0023357599 | AW8: =+AW7+1 -> 46205 | BL8: =SUM(AX8:BK8) -> 0 | BP8: =SUM(BL8:BO8) -> 0 | BQ8: =+'REKAPAN CHAMP SAPI'!AC5 -> 0 | BR8: =+BL8/BQ8 -> #DIV/0! | BS8: =+BM8/BQ8 -> #DIV/0! | BU8: =+BU7+1 -> 46205 | CJ8: =SUM(BV8:CI8) -> 0 | CN8: =SUM(CJ8:CM8) -> 0 | CO8: =+'REKAPAN CHAMP OTAK-OTAK'!AC5 -> 0 | CP8: =+CJ8/CO8 -> #DIV/0! | CQ8: =+CK8/CO8 -> #DIV/0! | CS8: =+CS7+1 -> 46205 | DH8: =SUM(CT8:DG8) -> 0 | DL8: =SUM(DH8:DK8) -> 0 | DM8: =+'REKAPAN CHAMP OTAK-OTAK'!AY5 -> 0 | DN8: =+DH8/DM8 -> #DIV/0! | DO8: =+DI8/DM8 -> #DIV/0! | DQ8: =+B8+Z8+AX8+BV8+CT8 -> 0 | DR8: =+C8+AA8+AY8+BW8+CU8 -> 0 | DS8: =+D8+AB8+AZ8+BX8+CV8 -> 6 | DT8: =+E8+AC8+BA8+BY8+CW8 -> 5 | DU8: =+F8+AD8+BB8+BZ8+CX8 -> 0.5 | DV8: =+G8+AE8+BC8+CA8+CY8 -> 5.5 | DW8: =+H8+AF8+BD8+CB8+CZ8 -> 9.5 | DX8: =+I8+AG8+BE8+CC8+DA8 -> 0 | ... ED8: =+O8+AM8+BK8+CI8+DG8 -> 1.5 | EE8: =SUM(DQ8:ED8) -> 52.5 | EF8: =+Q8+AO8+BM8+CK8+DI8 -> 35.5 | EG8: =+R8+AP8+BN8+CL8+DJ8 -> 0 | EH8: =+S8+AQ8+BO8+CM8+DK8 -> 0 | EI8: =SUM(EE8:EH8) -> 88 | EJ8: =+U8+AS8+BQ8+CO8+DM8 -> 15198.48 | EK8: =+EE8/EJ8 -> 0.0034542928 | EL8: =+EF8/EJ8 -> 0.0023357599
A9: =+A8+1 -> 46206 | P9: =SUM(B9:O9) -> 0 | T9: =SUM(P9:S9) -> 0 | U9: =+'REKAPAN OKEY AYAM'!AC6 -> 0 | V9: =+P9/U9 -> #DIV/0! | W9: =+Q9/U9 -> #DIV/0! | Y9: =+Y8+1 -> 46206 | Z9: =1+1 -> 2 | AB9: =1+1+1+1+1+1+1 -> 7 | AC9: =1+1+1.5+1 -> 4.5 | AD9: 1 | AE9: =1+1+1+1+1+1 -> 6 | AF9: 2 | AH9: =1+1+1.5+1.5+1.5+1 -> 7.5 | AJ9: =1+1+1.5+1 -> 4.5 | AK9: =2+2+1 -> 5 | AL9: =1+1+1+1.5+1.5+1.5 -> 7.5 | AM9: 1 | AN9: =SUM(Z9:AM9) -> 48 | AO9: =4+4+4+5+6+5+6+8 -> 42 | AR9: =SUM(AN9:AQ9) -> 90 | AS9: =+'REKAPAN CHAMP AYAM'!AC6 -> 13509.76 | AT9: =+AN9/AS9 -> 0.0035529869 | AU9: =+AO9/AS9 -> 0.0031088635 | AW9: =+AW8+1 -> 46206 | BL9: =SUM(AX9:BK9) -> 0 | BP9: =SUM(BL9:BO9) -> 0 | BQ9: =+'REKAPAN CHAMP SAPI'!AC6 -> 0 | BR9: =+BL9/BQ9 -> #DIV/0! | BS9: =+BM9/BQ9 -> #DIV/0! | BU9: =+BU8+1 -> 46206 | CJ9: =SUM(BV9:CI9) -> 0 | CN9: =SUM(CJ9:CM9) -> 0 | CO9: =+'REKAPAN CHAMP OTAK-OTAK'!AC6 -> 0 | CP9: =+CJ9/CO9 -> #DIV/0! | CQ9: =+CK9/CO9 -> #DIV/0! | CS9: =+CS8+1 -> 46206 | DH9: =SUM(CT9:DG9) -> 0 | DL9: =SUM(DH9:DK9) -> 0 | DM9: =+'REKAPAN CHAMP OTAK-OTAK'!AY6 -> 0 | DN9: =+DH9/DM9 -> #DIV/0! | DO9: =+DI9/DM9 -> #DIV/0! | DQ9: =+B9+Z9+AX9+BV9+CT9 -> 2 | DR9: =+C9+AA9+AY9+BW9+CU9 -> 0 | DS9: =+D9+AB9+AZ9+BX9+CV9 -> 7 | DT9: =+E9+AC9+BA9+BY9+CW9 -> 4.5 | DU9: =+F9+AD9+BB9+BZ9+CX9 -> 1 | DV9: =+G9+AE9+BC9+CA9+CY9 -> 6 | DW9: =+H9+AF9+BD9+CB9+CZ9 -> 2 | DX9: =+I9+AG9+BE9+CC9+DA9 -> 0 | ... ED9: =+O9+AM9+BK9+CI9+DG9 -> 1 | EE9: =SUM(DQ9:ED9) -> 48 | EF9: =+Q9+AO9+BM9+CK9+DI9 -> 42 | EG9: =+R9+AP9+BN9+CL9+DJ9 -> 0 | EH9: =+S9+AQ9+BO9+CM9+DK9 -> 0 | EI9: =SUM(EE9:EH9) -> 90 | EJ9: =+U9+AS9+BQ9+CO9+DM9 -> 13509.76 | EK9: =+EE9/EJ9 -> 0.0035529869 | EL9: =+EF9/EJ9 -> 0.0031088635
A10: =+A9+1 -> 46207 | P10: =SUM(B10:O10) -> 0 | T10: =SUM(P10:S10) -> 0 | U10: =+'REKAPAN OKEY AYAM'!AC7 -> 0 | V10: =+P10/U10 -> #DIV/0! | W10: =+Q10/U10 -> #DIV/0! | Y10: =+Y9+1 -> 46207 | AN10: =SUM(Z10:AM10) -> 0 | AR10: =SUM(AN10:AQ10) -> 0 | AS10: =+'REKAPAN CHAMP AYAM'!AC7 -> 0 | AT10: =+AN10/AS10 -> #DIV/0! | AU10: =+AO10/AS10 -> #DIV/0! | AW10: =+AW9+1 -> 46207 | BL10: =SUM(AX10:BK10) -> 0 | BP10: =SUM(BL10:BO10) -> 0 | BQ10: =+'REKAPAN CHAMP SAPI'!AC7 -> 0 | BR10: =+BL10/BQ10 -> #DIV/0! | BS10: =+BM10/BQ10 -> #DIV/0! | BU10: =+BU9+1 -> 46207 | CJ10: =SUM(BV10:CI10) -> 0 | CN10: =SUM(CJ10:CM10) -> 0 | CO10: =+'REKAPAN CHAMP OTAK-OTAK'!AC7 -> 0 | CP10: =+CJ10/CO10 -> #DIV/0! | CQ10: =+CK10/CO10 -> #DIV/0! | CS10: =+CS9+1 -> 46207 | DH10: =SUM(CT10:DG10) -> 0 | DL10: =SUM(DH10:DK10) -> 0 | DM10: =+'REKAPAN CHAMP OTAK-OTAK'!AY7 -> 0 | DN10: =+DH10/DM10 -> #DIV/0! | DO10: =+DI10/DM10 -> #DIV/0! | DQ10: =+B10+Z10+AX10+BV10+CT10 -> 0 | DR10: =+C10+AA10+AY10+BW10+CU10 -> 0 | DS10: =+D10+AB10+AZ10+BX10+CV10 -> 0 | DT10: =+E10+AC10+BA10+BY10+CW10 -> 0 | DU10: =+F10+AD10+BB10+BZ10+CX10 -> 0 | DV10: =+G10+AE10+BC10+CA10+CY10 -> 0 | DW10: =+H10+AF10+BD10+CB10+CZ10 -> 0 | DX10: =+I10+AG10+BE10+CC10+DA10 -> 0 | ... ED10: =+O10+AM10+BK10+CI10+DG10 -> 0 | EE10: =SUM(DQ10:ED10) -> 0 | EF10: =+Q10+AO10+BM10+CK10+DI10 -> 0 | EG10: =+R10+AP10+BN10+CL10+DJ10 -> 0 | EH10: =+S10+AQ10+BO10+CM10+DK10 -> 0 | EI10: =SUM(EE10:EH10) -> 0 | EJ10: =+U10+AS10+BQ10+CO10+DM10 -> 0 | EK10: =+EE10/EJ10 -> #DIV/0! | EL10: =+EF10/EJ10 -> #DIV/0!
A11: =+A10+1 -> 46208 | P11: =SUM(B11:O11) -> 0 | T11: =SUM(P11:S11) -> 0 | U11: =+'REKAPAN OKEY AYAM'!AC8 -> 0 | V11: =+P11/U11 -> #DIV/0! | W11: =+Q11/U11 -> #DIV/0! | Y11: =+Y10+1 -> 46208 | AN11: =SUM(Z11:AM11) -> 0 | AR11: =SUM(AN11:AQ11) -> 0 | AS11: =+'REKAPAN CHAMP AYAM'!AC8 -> 0 | AT11: =+AN11/AS11 -> #DIV/0! | AU11: =+AO11/AS11 -> #DIV/0! | AW11: =+AW10+1 -> 46208 | BL11: =SUM(AX11:BK11) -> 0 | BP11: =SUM(BL11:BO11) -> 0 | BQ11: =+'REKAPAN CHAMP SAPI'!AC8 -> 0 | BR11: =+BL11/BQ11 -> #DIV/0! | BS11: =+BM11/BQ11 -> #DIV/0! | BU11: =+BU10+1 -> 46208 | CJ11: =SUM(BV11:CI11) -> 0 | CN11: =SUM(CJ11:CM11) -> 0 | CO11: =+'REKAPAN CHAMP OTAK-OTAK'!AC8 -> 0 | CP11: =+CJ11/CO11 -> #DIV/0! | CQ11: =+CK11/CO11 -> #DIV/0! | CS11: =+CS10+1 -> 46208 | DH11: =SUM(CT11:DG11) -> 0 | DL11: =SUM(DH11:DK11) -> 0 | DM11: =+'REKAPAN CHAMP OTAK-OTAK'!AY8 -> 0 | DN11: =+DH11/DM11 -> #DIV/0! | DO11: =+DI11/DM11 -> #DIV/0! | DQ11: =+B11+Z11+AX11+BV11+CT11 -> 0 | DR11: =+C11+AA11+AY11+BW11+CU11 -> 0 | DS11: =+D11+AB11+AZ11+BX11+CV11 -> 0 | DT11: =+E11+AC11+BA11+BY11+CW11 -> 0 | DU11: =+F11+AD11+BB11+BZ11+CX11 -> 0 | DV11: =+G11+AE11+BC11+CA11+CY11 -> 0 | DW11: =+H11+AF11+BD11+CB11+CZ11 -> 0 | DX11: =+I11+AG11+BE11+CC11+DA11 -> 0 | ... ED11: =+O11+AM11+BK11+CI11+DG11 -> 0 | EE11: =SUM(DQ11:ED11) -> 0 | EF11: =+Q11+AO11+BM11+CK11+DI11 -> 0 | EG11: =+R11+AP11+BN11+CL11+DJ11 -> 0 | EH11: =+S11+AQ11+BO11+CM11+DK11 -> 0 | EI11: =SUM(EE11:EH11) -> 0 | EJ11: =+U11+AS11+BQ11+CO11+DM11 -> 0 | EK11: =+EE11/EJ11 -> #DIV/0! | EL11: =+EF11/EJ11 -> #DIV/0!
A12: =+A11+1 -> 46209 | D12: 5 | G12: 5 | H12: 5 | J12: 5 | P12: =SUM(B12:O12) -> 20 | Q12: 2 | T12: =SUM(P12:S12) -> 22 | U12: =+'REKAPAN OKEY AYAM'!AC9 -> 1578.68 | V12: =+P12/U12 -> 0.012668812 | W12: =+Q12/U12 -> 0.0012668812 | Y12: =+Y11+1 -> 46209 | AN12: =SUM(Z12:AM12) -> 0 | AR12: =SUM(AN12:AQ12) -> 0 | AS12: =+'REKAPAN CHAMP AYAM'!AC9 -> 0 | AT12: =+AN12/AS12 -> #DIV/0! | AU12: =+AO12/AS12 -> #DIV/0! | AW12: =+AW11+1 -> 46209 | BL12: =SUM(AX12:BK12) -> 0 | BP12: =SUM(BL12:BO12) -> 0 | BQ12: =+'REKAPAN CHAMP SAPI'!AC9 -> 0 | BR12: =+BL12/BQ12 -> #DIV/0! | BS12: =+BM12/BQ12 -> #DIV/0! | BU12: =+BU11+1 -> 46209 | CJ12: =SUM(BV12:CI12) -> 0 | CN12: =SUM(CJ12:CM12) -> 0 | CO12: =+'REKAPAN CHAMP OTAK-OTAK'!AC9 -> 0 | CP12: =+CJ12/CO12 -> #DIV/0! | CQ12: =+CK12/CO12 -> #DIV/0! | CS12: =+CS11+1 -> 46209 | DH12: =SUM(CT12:DG12) -> 0 | DL12: =SUM(DH12:DK12) -> 0 | DM12: =+'REKAPAN CHAMP OTAK-OTAK'!AY9 -> 0 | DN12: =+DH12/DM12 -> #DIV/0! | DO12: =+DI12/DM12 -> #DIV/0! | DQ12: =+B12+Z12+AX12+BV12+CT12 -> 0 | DR12: =+C12+AA12+AY12+BW12+CU12 -> 0 | DS12: =+D12+AB12+AZ12+BX12+CV12 -> 5 | DT12: =+E12+AC12+BA12+BY12+CW12 -> 0 | DU12: =+F12+AD12+BB12+BZ12+CX12 -> 0 | DV12: =+G12+AE12+BC12+CA12+CY12 -> 5 | DW12: =+H12+AF12+BD12+CB12+CZ12 -> 5 | DX12: =+I12+AG12+BE12+CC12+DA12 -> 0 | ... ED12: =+O12+AM12+BK12+CI12+DG12 -> 0 | EE12: =SUM(DQ12:ED12) -> 20 | EF12: =+Q12+AO12+BM12+CK12+DI12 -> 2 | EG12: =+R12+AP12+BN12+CL12+DJ12 -> 0 | EH12: =+S12+AQ12+BO12+CM12+DK12 -> 0 | EI12: =SUM(EE12:EH12) -> 22 | EJ12: =+U12+AS12+BQ12+CO12+DM12 -> 1578.68 | EK12: =+EE12/EJ12 -> 0.012668812 | EL12: =+EF12/EJ12 -> 0.0012668812
